Workbook

Sheet Budget Courant
A2: Income
I3: Other
F4: Total Income | G4: =SUM(C5:C8) -> 6096.32
A5: Eric | C5: 3673.32
A6: Maryse | C6: 2123 | F6: Total Recurring | G6: =SUM(C13+C17+C22+K13+K15+O15+G13+G16+G23+G25+G27+O13+O17+O19+O21+K17+K19) -> 3828.46
A8: Gouv | C8: 300 | F8: What's left | G8: =SUM(G4-G6) -> 2267.86
A10: Expenses
A13: 🏡 Maison | C13: =SUM(C14:C15) -> 1043.33 | E13: 💵 Pret | G13: =SUM(G14:G15) -> 118.01 | I13: 📺 Videotron | K13: 175.23 | M13: 🐱 Animaux | O13: 50
B14: Loyer | C14: 940 | F14: Etude Eric | G14: 118.01
B15: Hydro | C15: 103.33 | I15: 📱 Koodo | K15: 62.64 | M15: 🎓 Kaleido | O15: 31.02
E16: 🧾 Abonnements | G16: =SUM(G17:G21) -> 67.79
A17: 📃 Assurance | C17: =SUM(C18:C20) -> 181.1 | F17: Spotify | G17: 18.38 | I17: 🍽 Restaurants | K17: 200 | M17: 💸 Investissement | O17: 25
B18: Maison | C18: 35.6 | F18: Netflix | G18: 17.23
B19: Auto | C19: 135.89 | F19: Google Storage | G19: 3.21 | I19: 🦷 Dentiste | K19: 30 | M19: 🏫 Service de garde | O19: 170
B20: Vie | C20: 9.61 | F20: Amazon | G20: 9.44
F21: Xbox | G21: 19.53 | I21: 💈 Barbier | J21: Barbier | K21: 30 | M21: 🍺 Alcool | O21: 100
A22: 🚙 Auto | C22: =SUM(C23:C26) -> 874.34
B23: Jeep | C23: 429.34 | E23: 💰 Finance | G23: 40
B24: Gas | C24: 400
B25: Plaque | C25: 30 | E25: 🍏 Epicerie | G25: 600
B26: Permis | C26: 15
E27: 🧻 Pharmacie | G27: =SUM(G28:G29) -> 60
F28: Achats | G28: 40
F29: Medicament | G29: 20

Sheet Mensuel
A2: Income
I3: Other
F4: Income | G4: =SUM(C5:C10) -> 7735.09 | I4: Emergency Fund
A5: Eric | C5: =(951.52*52)/12 -> 4123.2533
A6: Maryse | C6: =(611*50)/12 -> 2545.8333 | F6: Recurring | G6: =SUM(C15,C20,C26,G15,G21,G24,G26,K15,K17,K19,K22,K24,K26,K28,O17,O19,O15) -> 5237.4667 | I6: Target | K6: =G6*3-(K28+K26) -> 15400.23
I7: Current | K7: 5892
A8: Gouv Qc | C8: =((1060.07*3)+1314.07)/12 -> 374.52333 | F8: What's left | G8: =SUM(G4-G6) -> 2497.6233 | I8: Missing | K8: =K6-K7 -> 9508.23
A9: Gouv Can | C9: 691.48
A10: Crédit Garderie | C10: 0
A12: Expenses
A15: 🏡 Maison | C15: =SUM(C16:C18) -> 2050 | E15: 🧾 Abonnements | G15: =SUM(G16:G20) -> 73.64 | I15: 📱 Fizz | K15: =85.07 -> 85.07 | M15: 🏫 Garderie | O15: 200
B16: Loyer | C16: 1680 | F16: Spotify | G16: 24.13
B17: Hydro | C17: 170 | F17: Netflix (-8$ parents) | G17: 31.02 | I17: 🍽 Restaurants | K17: 100 | M17: 🏫 Service de garde | O17: 180
B18: Taxes | C18: 200 | F18: Google Storage | G18: 7
F19: Amazon | G19: 11.49 | I19: 🦷 Dentiste | K19: =30+K20 -> 205 | M19: 🍺 Autres | O19: 40
A20: 📃 Assurance | C20: =SUM(C21:C24) -> 324.92 | I20: Orthodonthie Alexa | K20: 175
B21: Maison (964 année) | C21: 80.38 | E21: 💰 Finance | G21: =G22 -> 40
B22: Auto (1513 année) | C22: 98.54 | F22: Frais de compte | G22: 40 | I22: 💈 Barbier | K22: =50*(52/5)/12 -> 43.333333
B23: Vie | C23: 12
B24: Ass. Vie -Hypothèque | C24: 134 | E24: 🍏 Epicerie | G24: =((175*52)/12)+50 -> 808.33333 | I24: 🐱 Animaux | K24: 80
A26: 🚙 Auto | C26: =SUM(C27:C29) -> 585 | E26: 🧻 Pharmacie | G26: =SUM(G27:G29) -> 110 | I26: 🎓 Kaleido | K26: 62.17
B27: Gas | C27: 540 | F27: Achats | G27: 40
B28: Plaque | C28: 30 | F28: Medicament | G28: 20 | I28: 💸 Investissement | K28: 250
B29: Permis | C29: 15 | F29: Bébé | G29: 50

Sheet Investissements
B3: Date | C3: CELI | D3: REER | E3: REEE | F3: Total
B5: 45323 | C5: =2075.83+5350.84+1217.01 -> 8643.68 | D5: =1230.19+1129.49+8008.1 -> 10367.78 | E5: 3935.24 | F5: =SUM(C5:E5) -> 22946.7
B6: 45352 | C6: =2129.72+3831.56+1230.19 -> 7191.47 | D6: =1230.19+1158.8+8873.45 -> 11262.44 | E6: =3968.23+245.38 -> 4213.61 | F6: =SUM(C6:E6) -> 22667.52
B7: Mai 2024 | C7: =2185.73+3701.98+1062.53 -> 6950.24 | D7: =1230.19+1189.27+9642.64 -> 12062.1 | E7: =4128.92+385.75 -> 4514.67 | F7: =SUM(C7:E7) -> 23527.01
B8: 45658 | C8: =1366+4057+2385 -> 7808 | D8: =1297+1230+14244 -> 16771 | E8: =4464+708 -> 5172 | F8: =SUM(C8:E8) -> 29751
B9: 45778 | C9: =2238.23+4223.04+1268.71 -> 7729.98 | D9: =2341.88+15879.14 -> 18221.02 | E9: =4642.03+850.43 -> 5492.46 | F9: =SUM(C9:E9) -> 31443.46
B10: Sept 2025 | C10: =2629.18+679.02+972.33+5006.52 -> 9287.05 | D10: =2748.88+18207.32 -> 20956.2 | E10: =1159.82+4890.61 -> 6050.43 | F10: =SUM(C10:E10) -> 36293.68

Sheet 2025
A1: 2025 | B1: Janvier | D1: Février | F1: Mars | H1: Avril | J1: Mai | L1: Juin | N1: Juillet | P1: Aout | R1: Septembre | S1: Octobre | T1: Novembre | U1: Décembre | W1: Total Budget | X1: Total Reel
B2: Budget | C2: Réel | D2: Budget | E2: Réel | F2: Budget | G2: Réel | H2: Budget | I2: Réel | J2: Budget | K2: Réel | L2: Budget | M2: Réel | N2: Budget | O2: Réel | P2: Budget | Q2: Réel
A4: Total Mois | B4: =B7-(SUM(B14,B20,B27,B35,B41,B48) ) -> #REF! | C4: =C7-(SUM(C14,C20,C27,C35,C41,C48) ) -> 3715.98 | D4: =D7-(SUM(D14,D20,D27,D35,D41,D48) ) -> #REF! | E4: =E7-(SUM(E14,E20,E27,E35,E41,E48) ) -> 2662.76 | F4: =F7-(SUM(F14,F20,F27,F35,F41,F48) ) -> #REF! | G4: =G7-(SUM(G14,G20,G27,G35,G41,G48) ) -> -697.58 | H4: =H7-(SUM(H14,H20,H27,H35,H41,H48) ) -> #REF! | I4: =I7-(SUM(I14,I20,I27,I35,I41,I48) ) -> 1194.49 | ... U4: =U7-(SUM(U14,U20,U27,U35,U41,U48) ) -> 2653.8533 | W4: =W7-(SUM(W14,W20,W27,W35,W41,W48) ) -> #REF! | X4: =SUM(E4,G4,I4,B4, K4, M4,4,Q4,R4,S4,T4,U4) -> #REF!
A5: Diff Budget | C5: =C4-B4 -> #REF! | E5: =E4-D4 -> #REF! | G5: =G4-F4 -> #REF! | I5: =I4-H4 -> #REF! | K5: =K4-J4 -> #REF! | M5: =M4-L4 -> #REF! | O5: =O4-N4 -> -3493.6933 | Q5: =Q4-P4 -> -2447.4733 | X5: =X4-W4 -> #REF!
A7: REVENU | B7: =SUM(B8:B12) -> 9147.5767 | C7: =SUM(C8:C12) -> 8661.92 | D7: =SUM(D8:D12) -> 7319.0533 | E7: =SUM(E8:E12) -> 7590.95 | F7: =SUM(F8:F12) -> 8076.6067 | G7: =SUM(G8:G12) -> 7559.13 | H7: =SUM(H8:H12) -> 9147.5767 | I7: =SUM(I8:I12) -> 3521.87 | ... U7: =SUM(U8:U12) -> 7360.5667 | W7: =SUM(W8:W11) -> 91853.127 | X7: =SUM(E7,G7,I7,K7,M7,O7,Q7,R7:U7) -> 49185.187
A8: Eric | B8: =Mensuel!$C$5 -> 4123.2533 | C8: 3811.84 | D8: =Mensuel!$C$5 -> 4123.2533 | E8: 3811.84 | F8: =Mensuel!$C$5 -> 4123.2533 | G8: 3811.84 | H8: =Mensuel!$C$5 -> 4123.2533 | J8: =Mensuel!$C$5 -> 4123.2533 | L8: =Mensuel!$C$5 -> 4123.2533 | N8: =Mensuel!$C$5 -> 4123.2533 | P8: =Mensuel!$C$5 -> 4123.2533 | R8: =Mensuel!$C$5 -> 4123.2533 | S8: =Mensuel!$C$5 -> 4123.2533 | T8: =Mensuel!$C$5 -> 4123.2533 | U8: =Mensuel!$C$5 -> 4123.2533 | W8: =SUM(B8,D8,F8,H8,J8,L8,N8,P8,R8,S8,T8,U8) -> 49479.04 | X8: =SUM(E8,G8,I8,K8,M8,O8,Q8,R8:U8) -> 24116.693
A9: Maryse | B9: =Mensuel!$C$6 -> 2545.8333 | C9: 2431.25 | D9: =894.14*2 -> 1788.28 | E9: 2431.25 | F9: =Mensuel!$C$6 -> 2545.8333 | G9: 2431.25 | H9: =Mensuel!$C$6 -> 2545.8333 | J9: =Mensuel!$C$6 -> 2545.8333 | L9: =Mensuel!$C$6 -> 2545.8333 | N9: =Mensuel!$C$6 -> 2545.8333 | P9: =Mensuel!$C$6 -> 2545.8333 | R9: =Mensuel!$C$6 -> 2545.8333 | S9: =Mensuel!$C$6 -> 2545.8333 | T9: =Mensuel!$C$6 -> 2545.8333 | U9: =Mensuel!$C$6 -> 2545.8333 | W9: =SUM(B9,D9,F9,H9,J9,L9,N9,P9,R9,S9,T9,U9) -> 29792.447 | X9: =SUM(E9,G9,I9,K9,M9,O9,Q9,R9:U9) -> 15045.833
A10: Gouv Qc | B10: 1070.97 | C10: 1070.97 | H10: 1070.97 | I10: 1070.97 | N10: 1070.97 | S10: 1070.97 | W10: =SUM(B10,D10,F10,H10,J10,L10,N10,P10,R10,S10,T10,U10) -> 4283.88 | X10: =SUM(E10,G10,I10,K10,M10,O10,Q10,R10:U10) -> 2141.94
A11: Gouv Can | B11: =Mensuel!$C$9 -> 691.48 | C11: 631.82 | D11: =Mensuel!$C$9 -> 691.48 | E11: 631.82 | F11: =Mensuel!$C$9 -> 691.48 | G11: 600 | H11: =Mensuel!$C$9 -> 691.48 | I11: =650.9+1800 -> 2450.9 | J11: =Mensuel!$C$9 -> 691.48 | L11: =Mensuel!$C$9 -> 691.48 | N11: =Mensuel!$C$9 -> 691.48 | P11: =Mensuel!$C$9 -> 691.48 | R11: =Mensuel!$C$9 -> 691.48 | S11: =Mensuel!$C$9 -> 691.48 | T11: =Mensuel!$C$9 -> 691.48 | U11: =Mensuel!$C$9 -> 691.48 | W11: =SUM(B11,D11,F11,H11,J11,L11,N11,P11,R11,S11,T11,U11) -> 8297.76 | X11: =SUM(E11,G11,I11,K11,M11,O11,Q11,R11:U11) -> 6448.64
A12: Vers. anticipé | B12: 716.04 | C12: 716.04 | D12: 716.04 | E12: 716.04 | F12: 716.04 | G12: 716.04 | H12: 716.04 | J12: 716.04 | L12: 716.04 | N12: 716.04 | P12: 716.04 | R12: =Mensuel!$C$10 -> 0 | S12: =Mensuel!$C$10 -> 0 | T12: =Mensuel!$C$10 -> 0 | U12: =Mensuel!$C$10 -> 0 | X12: =SUM(E12,G12,I12,K12,M12,O12,Q12,R12:U12) -> 1432.08
A14: MAISON | B14: =sum(B15:B18) -> 1930.38 | C14: =sum(C15:C18) -> 2327.38 | D14: =sum(D15:D18) -> 1930.38 | E14: =sum(E15:E18) -> 2327.38 | F14: =sum(F15:F18) -> 1930.38 | G14: =sum(G15:G18) -> 2327.38 | H14: =sum(H15:H18) -> 1930.38 | I14: =sum(I15:I18) -> 2327.38 | ... U14: =sum(U15:U18) -> 1930.38 | W14: =SUM(W15:W18) -> 23164.56 | X14: =SUM(E14,G14,I14,K14,M14,O14,Q14,R14:U14) -> 14703.66
A15: Hypothèque | B15: =Mensuel!$C$16 -> 1680 | C15: 2077 | D15: =Mensuel!$C$16 -> 1680 | E15: 2077 | F15: =Mensuel!$C$16 -> 1680 | G15: 2077 | H15: =Mensuel!$C$16 -> 1680 | I15: 2077 | J15: =Mensuel!$C$16 -> 1680 | L15: =Mensuel!$C$16 -> 1680 | N15: =Mensuel!$C$16 -> 1680 | P15: =Mensuel!$C$16 -> 1680 | R15: =Mensuel!$C$16 -> 1680 | S15: =Mensuel!$C$16 -> 1680 | T15: =Mensuel!$C$16 -> 1680 | U15: =Mensuel!$C$16 -> 1680 | W15: =SUM(B15,D15,F15,H15,J15,L15,N15,P15,R15,S15,T15,U15) -> 20160 | X15: =SUM(E15,G15,I15,K15,M15,O15,Q15,R15:U15) -> 12951
A16: Hydro | B16: =Mensuel!$C$17 -> 170 | C16: 170 | D16: =Mensuel!$C$17 -> 170 | E16: 170 | F16: =Mensuel!$C$17 -> 170 | G16: 170 | H16: =Mensuel!$C$17 -> 170 | I16: 170 | J16: =Mensuel!$C$17 -> 170 | L16: =Mensuel!$C$17 -> 170 | N16: =Mensuel!$C$17 -> 170 | P16: =Mensuel!$C$17 -> 170 | R16: =Mensuel!$C$17 -> 170 | S16: =Mensuel!$C$17 -> 170 | T16: =Mensuel!$C$17 -> 170 | U16: =Mensuel!$C$17 -> 170 | W16: =SUM(B16,D16,F16,H16,J16,L16,N16,P16,R16,S16,T16,U16) -> 2040 | X16: =SUM(E16,G16,I16,K16,M16,O16,Q16,R16:U16) -> 1190
A17: Ass. Maison | B17: =Mensuel!$C$21 -> 80.38 | C17: 80.38 | D17: =Mensuel!$C$21 -> 80.38 | E17: 80.38 | F17: =Mensuel!$C$21 -> 80.38 | G17: 80.38 | H17: =Mensuel!$C$21 -> 80.38 | I17: 80.38 | J17: =Mensuel!$C$21 -> 80.38 | L17: =Mensuel!$C$21 -> 80.38 | N17: =Mensuel!$C$21 -> 80.38 | P17: =Mensuel!$C$21 -> 80.38 | R17: =Mensuel!$C$21 -> 80.38 | S17: =Mensuel!$C$21 -> 80.38 | T17: =Mensuel!$C$21 -> 80.38 | U17: =Mensuel!$C$21 -> 80.38 | W17: =SUM(B17,D17,F17,H17,J17,L17,N17,P17,R17,S17,T17,U17) -> 964.56 | X17: =SUM(E17,G17,I17,K17,M17,O17,Q17,R17:U17) -> 562.66
A18: Taxes Scolaire
A20: AUTO | B20: =SUM(B21:B25) -> #REF! | C20: =SUM(C21:C25) -> 539.29 | D20: =SUM(D21:D25) -> #REF! | E20: =SUM(E21:E25) -> 514.54 | F20: =SUM(F21:F25) -> #REF! | G20: =SUM(G21:G25) -> 1112.33 | H20: =SUM(H21:H25) -> #REF! | I20: =SUM(I21:I25) -> 0 | ... U20: =SUM(U21:U25) -> 666.12 | W20: =SUM(W21:W24) -> #REF! | X20: =SUM(E20,G20,I20,K20,M20,O20,Q20,R20:U20) -> 4291.35
A21: Jeep | B21: =#REF! -> #REF! | C21: 416 | D21: =#REF! -> #REF! | E21: 416 | F21: =#REF! -> #REF! | G21: 416 | H21: =#REF! -> #REF! | J21: =#REF! -> #REF! | L21: =#REF! -> #REF! | W21: =SUM(B21,D21,F21,H21,J21,L21,N21,P21,R21,S21,T21,U21) -> #REF! | X21: =SUM(E21,G21,I21,K21,M21,O21,Q21,R21:U21) -> 832
A22: Plaques/Permis | B22: 24.75 | C22: 24.75 | F22: 210.32 | G22: 210.32 | J22: 202.74 | N22: 24.75 | W22: =SUM(B22,D22,F22,H22,J22,L22,N22,P22,R22,S22,T22,U22) -> 462.56 | X22: =SUM(E22,G22,I22,K22,M22,O22,Q22,R22:U22) -> 210.32
A23: Ass. Auto | B23: =Mensuel!$C$22 -> 98.54 | C23: 98.54 | D23: =Mensuel!$C$22 -> 98.54 | E23: 98.54 | F23: =Mensuel!$C$22 -> 98.54 | G23: 98.54 | H23: =Mensuel!$C$22 -> 98.54 | J23: =Mensuel!$C$22 -> 98.54 | L23: =Mensuel!$C$22 -> 98.54 | N23: =Mensuel!$C$22 -> 98.54 | P23: =Mensuel!$C$22 -> 98.54 | R23: 126.12 | S23: 126.12 | T23: 126.12 | U23: 126.12 | W23: =SUM(B23,D23,F23,H23,J23,L23,N23,P23,R23,S23,T23,U23) -> 1292.8 | X23: =SUM(E23,G23,I23,K23,M23,O23,Q23,R23:U23) -> 701.56
A24: Gas | B24: =Mensuel!$C$27 -> 540 | D24: =Mensuel!$C$27 -> 540 | F24: =Mensuel!$C$27 -> 540 | G24: =268.33+65.86+53.28 -> 387.47 | H24: =Mensuel!$C$27 -> 540 | J24: =Mensuel!$C$27 -> 540 | L24: =Mensuel!$C$27 -> 540 | N24: =Mensuel!$C$27 -> 540 | P24: =Mensuel!$C$27 -> 540 | R24: =Mensuel!$C$27 -> 540 | S24: =Mensuel!$C$27 -> 540 | T24: =Mensuel!$C$27 -> 540 | U24: =Mensuel!$C$27 -> 540 | W24: =SUM(B24,D24,F24,H24,J24,L24,N24,P24,R24,S24,T24,U24) -> 6480 | X24: =SUM(E24,G24,I24,K24,M24,O24,Q24,R24:U24) -> 2547.47
A25: Entretien | H25: =120+160+300+500 -> 1080
A27: FINANCE | B27: =SUM(B28:B33) -> 1803.17 | C27: =sum(C28:C33) -> 1611.63 | D27: =SUM(D28:D33) -> 1803.17 | E27: =SUM(E28:E33) -> 1612.63 | F27: =SUM(F28:F33) -> 1803.17 | G27: =sum(G28:G33) -> 1611.63 | H27: =SUM(H28:H33) -> 1803.17 | I27: =sum(I28:I33) -> 0 | J27: =SUM(J28:J33) -> 1803.17 | K27: =sum(K28:K33) -> 0 | L27: =SUM(L28:L33) -> 1803.17 | M27: =sum(M28:M33) -> 0 | N27: =SUM(N28:N33) -> 1803.17 | O27: =sum(O28:O33) -> 0 | P27: =SUM(P28:P33) -> 1803.17 | Q27: =sum(Q28:Q33) -> 0 | R27: =SUM(R28:R33) -> 803.17 | S27: =SUM(S28:S33) -> 803.17 | T27: =SUM(T28:T33) -> 803.17 | U27: =SUM(U28:U33) -> 803.17 | W27: =SUM(W28:W32) -> 15538.04 | X27: =SUM(E27,G27,I27,K27,M27,O27,Q27,R27:U27) -> 6436.94
A28: Frais comptes | B28: =Mensuel!$G$22 -> 40 | C28: =10.95+9.61+3.95+3.95 -> 28.46 | D28: =Mensuel!$G$22 -> 40 | E28: =10.95+9.61+3.95+3.95 -> 28.46 | F28: =Mensuel!$G$22 -> 40 | G28: =10.95+9.61+3.95+3.95 -> 28.46 | H28: =Mensuel!$G$22 -> 40 | J28: =Mensuel!$G$22 -> 40 | L28: =Mensuel!$G$22 -> 40 | N28: =Mensuel!$G$22 -> 40 | P28: =Mensuel!$G$22 -> 40 | R28: =Mensuel!$G$22 -> 40 | S28: =Mensuel!$G$22 -> 40 | T28: =Mensuel!$G$22 -> 40 | U28: =Mensuel!$G$22 -> 40 | W28: =SUM(B28,D28,F28,H28,J28,L28,N28,P28,R28,S28,T28,U28) -> 480 | X28: =SUM(E28,G28,I28,K28,M28,O28,Q28,R28:U28) -> 216.92
A29: Garderie | B29: 1200 | C29: 1200 | D29: 1200 | E29: 1200 | F29: 1200 | G29: 1200 | H29: 1200 | J29: 1200 | L29: 1200 | N29: 1200 | P29: 1200 | R29: =Mensuel!$O$15 -> 200 | S29: =Mensuel!$O$15 -> 200 | T29: =Mensuel!$O$15 -> 200 | U29: =Mensuel!$O$15 -> 200 | W29: =SUM(B29,D29,F29,H29,J29,L29,N29,P29,R29,S29,T29,U29) -> 10400 | X29: =SUM(E29,G29,I29,K29,M29,O29,Q29,R29:U29) -> 3200
A30: Kaleido | B30: =Mensuel!$K$26 -> 62.17 | C30: 62.17 | D30: =Mensuel!$K$26 -> 62.17 | E30: 62.17 | F30: =Mensuel!$K$26 -> 62.17 | G30: 62.17 | H30: =Mensuel!$K$26 -> 62.17 | J30: =Mensuel!$K$26 -> 62.17 | L30: =Mensuel!$K$26 -> 62.17 | N30: =Mensuel!$K$26 -> 62.17 | P30: =Mensuel!$K$26 -> 62.17 | R30: =Mensuel!$K$26 -> 62.17 | S30: =Mensuel!$K$26 -> 62.17 | T30: =Mensuel!$K$26 -> 62.17 | U30: =Mensuel!$K$26 -> 62.17 | W30: =SUM(B30,D30,F30,H30,J30,L30,N30,P30,R30,S30,T30,U30) -> 746.04 | X30: =SUM(E30,G30,I30,K30,M30,O30,Q30,R30:U30) -> 373.02
A31: Service de garde | B31: =Mensuel!$O$17 -> 180 | D31: =Mensuel!$O$17 -> 180 | E31: 1 | F31: =Mensuel!$O$17 -> 180 | H31: =Mensuel!$O$17 -> 180 | J31: 180 | L31: 180 | N31: 180 | P31: 180 | R31: 180 | S31: 180 | T31: 180 | U31: 180 | W31: =SUM(B31,D31,F31,H31,J31,L31,N31,P31,R31,S31,T31,U31) -> 2160 | X31: =SUM(E31,G31,I31,K31,M31,O31,Q31,R31:U31) -> 721
A32: Ass. Vie | B32: =Mensuel!$C$23+Mensuel!$C$24 -> 146 | C32: 146 | D32: =Mensuel!$C$23+Mensuel!$C$24 -> 146 | E32: 146 | F32: =Mensuel!$C$23+Mensuel!$C$24 -> 146 | G32: 146 | H32: =Mensuel!$C$23+Mensuel!$C$24 -> 146 | J32: =Mensuel!$C$23+Mensuel!$C$24 -> 146 | L32: =Mensuel!$C$23+Mensuel!$C$24 -> 146 | N32: =Mensuel!$C$23+Mensuel!$C$24 -> 146 | P32: =Mensuel!$C$23+Mensuel!$C$24 -> 146 | R32: =Mensuel!$C$23+Mensuel!$C$24 -> 146 | S32: =Mensuel!$C$23+Mensuel!$C$24 -> 146 | T32: =Mensuel!$C$23+Mensuel!$C$24 -> 146 | U32: =Mensuel!$C$23+Mensuel!$C$24 -> 146 | W32: =SUM(B32,D32,F32,H32,J32,L32,N32,P32,R32,S32,T32,U32) -> 1752 | X32: =SUM(E32,G32,I32,K32,M32,O32,Q32,R32:U32) -> 876
A33: Orthodonthie | B33: =Mensuel!$K$20 -> 175 | C33: 175 | D33: =Mensuel!$K$20 -> 175 | E33: 175 | F33: =Mensuel!$K$20 -> 175 | G33: 175 | H33: =Mensuel!$K$20 -> 175 | J33: =Mensuel!$K$20 -> 175 | L33: =Mensuel!$K$20 -> 175 | N33: =Mensuel!$K$20 -> 175 | P33: =Mensuel!$K$20 -> 175 | R33: =Mensuel!$K$20 -> 175 | S33: =Mensuel!$K$20 -> 175 | T33: =Mensuel!$K$20 -> 175 | U33: =Mensuel!$K$20 -> 175 | W33: =SUM(B33,D33,F33,H33,J33,L33,N33,P33,R33,S33,T33,U33) -> 2100 | X33: =SUM(E33,G33,I33,K33,M33,O33,Q33,R33:U33) -> 1050
A35: NOURRITURE | B35: =SUM(B36:B38) -> 1058.3333 | C35: =sum(C36:C39) -> 0 | D35: =SUM(D36:D38) -> 1058.3333 | E35: =sum(E36:E39) -> 0 | F35: =SUM(F36:F39) -> 1098.3333 | G35: =sum(G36:G39) -> 1371.73 | H35: =SUM(H36:H39) -> 1098.3333 | I35: =sum(I36:I39) -> 0 | J35: =SUM(J36:J39) -> 1098.3333 | K35: =sum(K36:K39) -> 0 | L35: =SUM(L36:L39) -> 1098.3333 | M35: =sum(M36:M39) -> 0 | N35: =SUM(N36:N39) -> 1098.3333 | O35: =sum(O36:O39) -> 0 | P35: =SUM(P36:P39) -> 1098.3333 | Q35: =sum(Q36:Q39) -> 0 | R35: =SUM(R36:R39) -> 1098.3333 | S35: =SUM(S36:S39) -> 1098.3333 | T35: =SUM(T36:T39) -> 1098.3333 | U35: =SUM(U36:U39) -> 1098.3333 | W35: =SUM(W36:W38) -> 12700 | X35: =SUM(E35,G35,I35,K35,M35,O35,Q35,R35:U35) -> 5765.0633
A36: Épicerie | B36: =Mensuel!$G$24+Mensuel!$O$19 -> 848.33333 | D36: =Mensuel!$G$24+Mensuel!$O$19 -> 848.33333 | F36: =Mensuel!$G$24+Mensuel!$O$19 -> 848.33333 | G36: =166+904 -> 1070 | H36: =Mensuel!$G$24+Mensuel!$O$19 -> 848.33333 | J36: =Mensuel!$G$24+Mensuel!$O$19 -> 848.33333 | L36: =Mensuel!$G$24+Mensuel!$O$19 -> 848.33333 | N36: =Mensuel!$G$24+Mensuel!$O$19 -> 848.33333 | P36: =Mensuel!$G$24+Mensuel!$O$19 -> 848.33333 | R36: =Mensuel!$G$24+Mensuel!$O$19 -> 848.33333 | S36: =Mensuel!$G$24+Mensuel!$O$19 -> 848.33333 | T36: =Mensuel!$G$24+Mensuel!$O$19 -> 848.33333 | U36: =Mensuel!$G$24+Mensuel!$O$19 -> 848.33333 | W36: =SUM(B36,D36,F36,H36,J36,L36,N36,P36,R36,S36,T36,U36) -> 10180 | X36: =SUM(E36,G36,I36,K36,M36,O36,Q36,R36:U36) -> 4463.3333
A37: Restaurant | B37: =Mensuel!$K$17 -> 100 | D37: =Mensuel!$K$17 -> 100 | F37: =Mensuel!$K$17 -> 100 | G37: =15.08+17.24+46.66+18.96 -> 97.94 | H37: =Mensuel!$K$17 -> 100 | J37: =Mensuel!$K$17 -> 100 | L37: =Mensuel!$K$17 -> 100 | N37: =Mensuel!$K$17 -> 100 | P37: =Mensuel!$K$17 -> 100 | R37: =Mensuel!$K$17 -> 100 | S37: =Mensuel!$K$17 -> 100 | T37: =Mensuel!$K$17 -> 100 | U37: =Mensuel!$K$17 -> 100 | W37: =SUM(B37,D37,F37,H37,J37,L37,N37,P37,R37,S37,T37,U37) -> 1200 | X37: =SUM(E37,G37,I37,K37,M37,O37,Q37,R37:U37) -> 497.94
A38: Pharmacie | B38: =Mensuel!$G$26 -> 110 | D38: =Mensuel!$G$26 -> 110 | F38: =Mensuel!$G$26 -> 110 | G38: =203.79-29.8-29.8 -> 144.19 | H38: =Mensuel!$G$26 -> 110 | J38: =Mensuel!$G$26 -> 110 | L38: =Mensuel!$G$26 -> 110 | N38: =Mensuel!$G$26 -> 110 | P38: =Mensuel!$G$26 -> 110 | R38: =Mensuel!$G$26 -> 110 | S38: =Mensuel!$G$26 -> 110 | T38: =Mensuel!$G$26 -> 110 | U38: =Mensuel!$G$26 -> 110 | W38: =SUM(B38,D38,F38,H38,J38,L38,N38,P38,R38,S38,T38,U38) -> 1320 | X38: =SUM(E38,G38,I38,K38,M38,O38,Q38,R38:U38) -> 584.19
A39: Extra | F39: =Mensuel!$O$19 -> 40 | G39: =29.8*2 -> 59.6 | H39: =Mensuel!$O$19 -> 40 | J39: =Mensuel!$O$19 -> 40 | L39: =Mensuel!$O$19 -> 40 | N39: =Mensuel!$O$19 -> 40 | P39: =Mensuel!$O$19 -> 40 | R39: =Mensuel!$O$19 -> 40 | S39: =Mensuel!$O$19 -> 40 | T39: =Mensuel!$O$19 -> 40 | U39: =Mensuel!$O$19 -> 40 | X39: =SUM(E39,G39,I39,K39,M39,O39,Q39,R39:U39) -> 219.6
A41: ABONNEMENTS | B41: =SUM(B42:B46) -> 158.71 | C41: =sum(C42:C46) -> 157.64 | D41: =SUM(D42:D46) -> 158.71 | E41: =SUM(E42:E46) -> 157.64 | F41: =SUM(F42:F46) -> 158.71 | G41: =sum(G42:G46) -> 157.64 | H41: =SUM(H42:H46) -> 158.71 | I41: =sum(I42:I46) -> 0 | J41: =SUM(J42:J46) -> 158.71 | K41: =sum(K42:K46) -> 0 | L41: =SUM(L42:L46) -> 158.71 | M41: =sum(M42:M46) -> 0 | N41: =SUM(N42:N46) -> 158.71 | O41: =sum(O42:O46) -> 0 | P41: =SUM(P42:P46) -> 158.71 | Q41: =sum(Q42:Q46) -> 0 | R41: =SUM(R42:R46) -> 158.71 | S41: =SUM(S42:S46) -> 158.71 | T41: =SUM(T42:T46) -> 158.71 | U41: =SUM(U42:U46) -> 158.71 | W41: =SUM(W42:W46) -> 1904.52 | X41: =SUM(E41,G41,I41,K41,M41,O41,Q41,R41:U41) -> 950.12
A42: Spotify | B42: =Mensuel!$G$16 -> 24.13 | C42: 24.13 | D42: =Mensuel!$G$16 -> 24.13 | E42: 24.13 | F42: =Mensuel!$G$16 -> 24.13 | G42: 24.13 | H42: =Mensuel!$G$16 -> 24.13 | J42: =Mensuel!$G$16 -> 24.13 | L42: =Mensuel!$G$16 -> 24.13 | N42: =Mensuel!$G$16 -> 24.13 | P42: =Mensuel!$G$16 -> 24.13 | R42: =Mensuel!$G$16 -> 24.13 | S42: =Mensuel!$G$16 -> 24.13 | T42: =Mensuel!$G$16 -> 24.13 | U42: =Mensuel!$G$16 -> 24.13 | W42: =SUM(B42,D42,F42,H42,J42,L42,N42,P42,R42,S42,T42,U42) -> 289.56 | X42: =SUM(E42,G42,I42,K42,M42,O42,Q42,R42:U42) -> 144.78
A43: Netflix | B43: =Mensuel!$G$17 -> 31.02 | C43: 31.02 | D43: =Mensuel!$G$17 -> 31.02 | E43: 31.02 | F43: =Mensuel!$G$17 -> 31.02 | G43: 31.02 | H43: =Mensuel!$G$17 -> 31.02 | J43: =Mensuel!$G$17 -> 31.02 | L43: =Mensuel!$G$17 -> 31.02 | N43: =Mensuel!$G$17 -> 31.02 | P43: =Mensuel!$G$17 -> 31.02 | R43: =Mensuel!$G$17 -> 31.02 | S43: =Mensuel!$G$17 -> 31.02 | T43: =Mensuel!$G$17 -> 31.02 | U43: =Mensuel!$G$17 -> 31.02 | W43: =SUM(B43,D43,F43,H43,J43,L43,N43,P43,R43,S43,T43,U43) -> 372.24 | X43: =SUM(E43,G43,I43,K43,M43,O43,Q43,R43:U43) -> 186.12
A44: Amazon | B44: =Mensuel!$G$19 -> 11.49 | C44: 11.49 | D44: =Mensuel!$G$19 -> 11.49 | E44: 11.49 | F44: =Mensuel!$G$19 -> 11.49 | G44: 11.49 | H44: =Mensuel!$G$19 -> 11.49 | J44: =Mensuel!$G$19 -> 11.49 | L44: =Mensuel!$G$19 -> 11.49 | N44: =Mensuel!$G$19 -> 11.49 | P44: =Mensuel!$G$19 -> 11.49 | R44: =Mensuel!$G$19 -> 11.49 | S44: =Mensuel!$G$19 -> 11.49 | T44: =Mensuel!$G$19 -> 11.49 | U44: =Mensuel!$G$19 -> 11.49 | W44: =SUM(B44,D44,F44,H44,J44,L44,N44,P44,R44,S44,T44,U44) -> 137.88 | X44: =SUM(E44,G44,I44,K44,M44,O44,Q44,R44:U44) -> 68.94
A45: Fizz | B45: =Mensuel!$K$15 -> 85.07 | C45: =22+19+43 -> 84 | D45: =Mensuel!$K$15 -> 85.07 | E45: =22+19+43 -> 84 | F45: =Mensuel!$K$15 -> 85.07 | G45: =22+19+43 -> 84 | H45: =Mensuel!$K$15 -> 85.07 | J45: =Mensuel!$K$15 -> 85.07 | L45: =Mensuel!$K$15 -> 85.07 | N45: =Mensuel!$K$15 -> 85.07 | P45: =Mensuel!$K$15 -> 85.07 | R45: =Mensuel!$K$15 -> 85.07 | S45: =Mensuel!$K$15 -> 85.07 | T45: =Mensuel!$K$15 -> 85.07 | U45: =Mensuel!$K$15 -> 85.07 | W45: =SUM(B45,D45,F45,H45,J45,L45,N45,P45,R45,S45,T45,U45) -> 1020.84 | X45: =SUM(E45,G45,I45,K45,M45,O45,Q45,R45:U45) -> 508.28
A46: Google | B46: =Mensuel!$G$18 -> 7 | C46: 7 | D46: =Mensuel!$G$18 -> 7 | E46: 7 | F46: =Mensuel!$G$18 -> 7 | G46: 7 | H46: =Mensuel!$G$18 -> 7 | J46: =Mensuel!$G$18 -> 7 | L46: =Mensuel!$G$18 -> 7 | N46: =Mensuel!$G$18 -> 7 | P46: =Mensuel!$G$18 -> 7 | R46: =Mensuel!$G$18 -> 7 | S46: =Mensuel!$G$18 -> 7 | T46: =Mensuel!$G$18 -> 7 | U46: =Mensuel!$G$18 -> 7 | W46: =SUM(B46,D46,F46,H46,J46,L46,N46,P46,R46,S46,T46,U46) -> 84 | X46: =SUM(E46,G46,I46,K46,M46,O46,Q46,R46:U46) -> 42
A48: Autre | B48: =SUM(B49:B75) -> 213 | C48: =SUM(C49:C75) -> 310 | D48: =SUM(D49:D75) -> 0 | E48: =SUM(E49:E59) -> 316 | F48: =SUM(F49:F75) -> 1417 | G48: =SUM(G49:G75) -> 1676 | H48: =SUM(H49:H75) -> 1520 | I48: =SUM(I49:I75) -> 0 | J48: =SUM(J49:J75) -> 1130 | K48: =SUM(K49:K75) -> 0 | L48: =SUM(L49:L75) -> 400 | M48: =SUM(M49:M75) -> 0 | ... U48: =SUM(U49:U75) -> 50 | W48: =SUM(W49:W59) -> 3934 | X48: =SUM(E48,G48,I48,K48,M48,O48,Q48,R48:U48) -> 2042
...

Sheet 2024
A1: 2024 | B1: Janvier | D1: Février | F1: Mars | H1: Avril | J1: Mai | L1: Juin | N1: Juillet | P1: Aout | R1: Septembre | S1: Octobre | T1: Novembre | U1: Décembre | W1: Total Budget | X1: Total Reel
B2: Budget | C2: Réel | D2: Budget | E2: Réel | F2: Budget | G2: Réel | H2: Budget | I2: Réel | J2: Budget | K2: Réel | L2: Budget | M2: Réel | N2: Budget | O2: Réel | P2: Budget | Q2: Réel
A4: Total Mois | B4: =B7-(SUM(B14,B21,B28,B36,B41,B48) ) -> #REF! | C4: =C7-(SUM(C14,C21,C28,C36,C41,C48) ) -> 2576.13 | D4: =D7-(SUM(D14,D21,D28,D36,D41,D48) ) -> #REF! | E4: =E7-(SUM(E14,E21,E28,E36,E41,E48) ) -> 485.27 | F4: =F7-(SUM(F14,F21,F28,F36,F41,F48) ) -> #REF! | G4: =G7-(SUM(G14,G21,G28,G36,G41,G48) ) -> -3192.59 | H4: =H7-(SUM(H14,H21,H28,H36,H41,H48) ) -> #REF! | I4: =I7-(SUM(I14,I21,I28,I36,I41,I48) ) -> -23.66 | ... U4: =U7-(SUM(U14,U21,U28,U36,U41,U48) ) -> #REF! | W4: =W7-(SUM(W14,W21,W28,W36,W41,W48) ) -> #REF! | X4: =SUM(E4,G4,I4,B4) -> #REF!
A5: Diff Budget | C5: =C4-B4 -> #REF! | E5: =E4-D4 -> #REF! | G5: =G4-F4 -> #REF! | I5: =I4-H4 -> #REF! | K5: =K4-J4 -> #REF! | M5: =M4-L4 -> #REF! | O5: =O4-N4 -> #REF! | Q5: =Q4-P4 -> #REF! | W5: =sum(W4-sum(G5,E5)) -> #REF!
A7: REVENU | B7: =SUM(B8:B11) -> 7673.9833 | C7: =SUM(C8:C11) -> 7668.4033 | D7: =SUM(D8:D11) -> 6603.0133 | E7: =SUM(E8:E11) -> 7193.9 | F7: =SUM(F8:F11) -> 6603.0133 | G7: =SUM(G8:G11) -> 6242.38 | H7: =SUM(H8:H11) -> 7673.9833 | I7: =SUM(I8:I11) -> 7392.38 | J7: =SUM(J8:J12) -> 7360.5667 | K7: =SUM(K8:K12) -> 6242.38 | L7: =SUM(L8:L12) -> 8316.0667 | M7: =SUM(M8:M12) -> 8572.17 | N7: =SUM(N8:N12) -> 9387.0367 | O7: =SUM(O8:O12) -> 8907.3 | P7: =SUM(P8:P12) -> 8316.0667 | Q7: =SUM(Q8:Q12) -> 0 | ... U7: =SUM(U8:U12) -> 8316.0667 | W7: =SUM(W8:W11) -> 89580.467 | X7: =SUM(E7,G7,I7,K7,M7,O7,Q7) -> 44550.51
A8: Eric | B8: =Mensuel!$C$5 -> 4123.2533 | C8: 4177.3333 | D8: =Mensuel!$C$5 -> 4123.2533 | E8: =951.52*5 -> 4757.6 | F8: =Mensuel!$C$5 -> 4123.2533 | G8: =951.52*4 -> 3806.08 | H8: =Mensuel!$C$5 -> 4123.2533 | I8: =4*951.52 -> 3806.08 | J8: =Mensuel!$C$5 -> 4123.2533 | K8: =4*951.52 -> 3806.08 | L8: =Mensuel!$C$5 -> 4123.2533 | M8: =4*951.52 -> 3806.08 | N8: =Mensuel!$C$5 -> 4123.2533 | O8: 3806.08 | P8: =Mensuel!$C$5 -> 4123.2533 | R8: =Mensuel!$C$5 -> 4123.2533 | S8: =Mensuel!$C$5 -> 4123.2533 | T8: =Mensuel!$C$5 -> 4123.2533 | U8: =Mensuel!$C$5 -> 4123.2533 | W8: =SUM(B8,D8,F8,H8,J8,L8,N8,P8,R8,S8,T8,U8) -> 49479.04 | X8: =SUM(E8,G8,I8,K8,M8,O8,Q8) -> 23788
A9: Maryse | B9: =894.14*2 -> 1788.28 | C9: 1788.28 | D9: =894.14*2 -> 1788.28 | E9: =902.24*2 -> 1804.48 | F9: =894.14*2 -> 1788.28 | G9: =902.24*2 -> 1804.48 | H9: =894.14*2 -> 1788.28 | I9: =902.24*2 -> 1804.48 | J9: =Mensuel!$C$6 -> 2545.8333 | K9: =902.24*2 -> 1804.48 | L9: =Mensuel!$C$6 -> 2545.8333 | M9: 2223.27 | N9: =Mensuel!$C$6 -> 2545.8333 | O9: 2376.57 | P9: =Mensuel!$C$6 -> 2545.8333 | R9: =Mensuel!$C$6 -> 2545.8333 | S9: =Mensuel!$C$6 -> 2545.8333 | T9: =Mensuel!$C$6 -> 2545.8333 | U9: =Mensuel!$C$6 -> 2545.8333 | W9: =SUM(B9,D9,F9,H9,J9,L9,N9,P9,R9,S9,T9,U9) -> 27519.787 | X9: =SUM(E9,G9,I9) -> 5413.44
A10: Gouv Qc | B10: 1070.97 | C10: 1070.97 | H10: 1070.97 | I10: 1150 | N10: 1070.97 | O10: 1138 | S10: 1070.97 | W10: =SUM(B10,D10,F10,H10,J10,L10,N10,P10,R10,S10,T10,U10) -> 4283.88 | X10: =SUM(E10,G10,I10) -> 1150
A11: Gouv Can | B11: =Mensuel!$C$9 -> 691.48 | C11: 631.82 | D11: =Mensuel!$C$9 -> 691.48 | E11: 631.82 | F11: =Mensuel!$C$9 -> 691.48 | G11: 631.82 | H11: =Mensuel!$C$9 -> 691.48 | I11: 631.82 | J11: =Mensuel!$C$9 -> 691.48 | K11: 631.82 | L11: =Mensuel!$C$9 -> 691.48 | M11: 631.82 | N11: =Mensuel!$C$9 -> 691.48 | O11: 631.82 | P11: =Mensuel!$C$9 -> 691.48 | R11: =Mensuel!$C$9 -> 691.48 | S11: =Mensuel!$C$9 -> 691.48 | T11: =Mensuel!$C$9 -> 691.48 | U11: =Mensuel!$C$9 -> 691.48 | W11: =SUM(B11,D11,F11,H11,J11,L11,N11,P11,R11,S11,T11,U11) -> 8297.76 | X11: =SUM(E11,G11,I11) -> 1895.46
A12: Vers. anticipé | L12: 955.5 | M12: =955.5*2 -> 1911 | N12: 955.5 | O12: 954.83 | P12: 955.5 | R12: 955.5 | S12: 955.5 | T12: 955.5 | U12: 955.5
A14: MAISON | B14: =sum(B15:B19) -> 2130.38 | C14: =sum(C15:C19) -> 2227.63 | D14: =sum(D15:D19) -> 2130.38 | E14: =sum(E15:E19) -> 2227.63 | F14: =sum(F15:F19) -> 2130.38 | G14: =sum(G15:G19) -> 2227.63 | H14: =sum(H15:H19) -> 2130.38 | I14: =sum(I15:I19) -> 2227.63 | ... U14: =sum(U15:U19) -> 2130.38 | W14: =SUM(W15:W19) -> 25564.56 | X14: =SUM(X15:X18) -> 10942.89
A15: Hypothèque | B15: =Mensuel!$C$16 -> 1680 | C15: 1420 | D15: =Mensuel!$C$16 -> 1680 | E15: 1420 | F15: =Mensuel!$C$16 -> 1680 | G15: 1420 | H15: =Mensuel!$C$16 -> 1680 | I15: 1420 | J15: =Mensuel!$C$16 -> 1680 | K15: 1420 | L15: =Mensuel!$C$16 -> 1680 | M15: 1420 | N15: =Mensuel!$C$16 -> 1680 | O15: 1420 | P15: =Mensuel!$C$16 -> 1680 | R15: =Mensuel!$C$16 -> 1680 | S15: =Mensuel!$C$16 -> 1680 | T15: =Mensuel!$C$16 -> 1680 | U15: =Mensuel!$C$16 -> 1680 | W15: =SUM(B15,D15,F15,H15,J15,L15,N15,P15,R15,S15,T15,U15) -> 20160 | X15: =SUM(E15,G15,I15,K15,M15,O15,Q15) -> 8520
A16: Vers. Anticipé | B16: =Mensuel!$C$18 -> 200 | C16: 600 | D16: =Mensuel!$C$18 -> 200 | E16: 600 | F16: =Mensuel!$C$18 -> 200 | G16: 600 | H16: =Mensuel!$C$18 -> 200 | I16: 600 | J16: =Mensuel!$C$18 -> 200 | K16: 600 | L16: =Mensuel!$C$18 -> 200 | M16: 600 | N16: =Mensuel!$C$18 -> 200 | O16: 600 | P16: =Mensuel!$C$18 -> 200 | Q16: 600 | R16: =Mensuel!$C$18 -> 200 | S16: =Mensuel!$C$18 -> 200 | T16: =Mensuel!$C$18 -> 200 | U16: =Mensuel!$C$18 -> 200 | W16: =SUM(B16,D16,F16,H16,J16,L16,N16,P16,R16,S16,T16,U16) -> 2400 | X16: =SUM(E16,G16,I16) -> 1800
A17: Hydro | B17: =Mensuel!$C$17 -> 170 | C17: 141.79 | D17: =Mensuel!$C$17 -> 170 | E17: 141.79 | F17: =Mensuel!$C$17 -> 170 | G17: 141.79 | H17: =Mensuel!$C$17 -> 170 | I17: 141.79 | J17: =Mensuel!$C$17 -> 170 | K17: 141.79 | L17: =Mensuel!$C$17 -> 170 | M17: 141.79 | N17: =Mensuel!$C$17 -> 170 | O17: 141.79 | P17: =Mensuel!$C$17 -> 170 | R17: =Mensuel!$C$17 -> 170 | S17: =Mensuel!$C$17 -> 170 | T17: =Mensuel!$C$17 -> 170 | U17: =Mensuel!$C$17 -> 170 | W17: =SUM(B17,D17,F17,H17,J17,L17,N17,P17,R17,S17,T17,U17) -> 2040 | X17: =SUM(E17,G17,I17) -> 425.37
A18: Ass. Maison | B18: =Mensuel!$C$21 -> 80.38 | C18: 65.84 | D18: =Mensuel!$C$21 -> 80.38 | E18: 65.84 | F18: =Mensuel!$C$21 -> 80.38 | G18: 65.84 | H18: =Mensuel!$C$21 -> 80.38 | I18: 65.84 | J18: =Mensuel!$C$21 -> 80.38 | K18: 65.84 | L18: =Mensuel!$C$21 -> 80.38 | M18: 80.38 | N18: =Mensuel!$C$21 -> 80.38 | O18: 80.38 | P18: =Mensuel!$C$21 -> 80.38 | Q18: 65.84 | R18: =Mensuel!$C$21 -> 80.38 | S18: =Mensuel!$C$21 -> 80.38 | T18: =Mensuel!$C$21 -> 80.38 | U18: =Mensuel!$C$21 -> 80.38 | W18: =SUM(B18,D18,F18,H18,J18,L18,N18,P18,R18,S18,T18,U18) -> 964.56 | X18: =SUM(E18,G18,I18) -> 197.52
A19: Taxes
A21: AUTO | B21: =SUM(B22:B26) -> #REF! | C21: =SUM(C22:C26) -> 1180.21 | D21: =SUM(D22:D26) -> #REF! | E21: =SUM(E22:E26) -> 1943.75 | F21: =SUM(F22:F26) -> #REF! | G21: =SUM(G22:G26) -> 1183.17 | H21: =SUM(H22:H26) -> #REF! | I21: =SUM(I22:I26) -> 1322.01 | ... U21: =SUM(U22:U26) -> #REF! | W21: =SUM(W22:W25) -> #REF! | X21: =SUM(X22:X26) -> 6446.38
A22: Jeep | B22: =#REF! -> #REF! | C22: 429.34 | D22: =#REF! -> #REF! | E22: =214.67*2 -> 429.34 | F22: =#REF! -> #REF! | G22: =214.67*2 -> 429.34 | H22: =#REF! -> #REF! | I22: =214.67*2 -> 429.34 | J22: =#REF! -> #REF! | K22: =214.67*2 -> 429.34 | L22: =#REF! -> #REF! | M22: =214.67*2 -> 429.34 | N22: =#REF! -> #REF! | O22: =214.67*2 -> 429.34 | P22: =#REF! -> #REF! | Q22: =214.67*2 -> 429.34 | R22: =#REF! -> #REF! | S22: =#REF! -> #REF! | T22: =#REF! -> #REF! | U22: =#REF! -> #REF! | W22: =SUM(B22,D22,F22,H22,J22,L22,N22,P22,R22,S22,T22,U22) -> #REF! | X22: =SUM(E22,G22,I22) -> 1288.02
A23: Plaques/Permis | B23: 24.75 | C23: 24.75 | F23: 210.32 | G23: 210.32 | J23: 202.74 | K23: 202.74 | N23: 24.75 | O23: 24.75 | W23: =SUM(B23,D23,F23,H23,J23,L23,N23,P23,R23,S23,T23,U23) -> 462.56 | X23: =SUM(E23,G23,I23,K23,M23,O23,Q23) -> 437.81
A24: Ass. Auto | B24: =Mensuel!$C$22 -> 98.54 | C24: 126.12 | D24: =Mensuel!$C$22 -> 98.54 | E24: 126.12 | F24: =Mensuel!$C$22 -> 98.54 | G24: 126.12 | H24: =Mensuel!$C$22 -> 98.54 | I24: 126.12 | J24: =Mensuel!$C$22 -> 98.54 | K24: 126.12 | L24: =Mensuel!$C$22 -> 98.54 | M24: 126.12 | N24: =Mensuel!$C$22 -> 98.54 | O24: 126.12 | P24: =Mensuel!$C$22 -> 98.54 | R24: 126.12 | S24: 126.12 | T24: 126.12 | U24: 126.12 | W24: =SUM(B24,D24,F24,H24,J24,L24,N24,P24,R24,S24,T24,U24) -> 1292.8 | X24: =SUM(E24,G24,I24,K24,M24,O24,Q24) -> 756.72
A25: Gas | B25: =Mensuel!$C$27 -> 540 | C25: 600 | D25: =Mensuel!$C$27 -> 540 | E25: =436.58+65 -> 501.58 | F25: =Mensuel!$C$27 -> 540 | G25: =54.57+61.37+15+61.76+15+73.32+60+76.37 -> 417.39 | H25: =Mensuel!$C$27 -> 540 | I25: =75.88+82.62+73.76+69.89+68.12+72.49+72.79 -> 515.55 | J25: =Mensuel!$C$27 -> 540 | K25: 574.6 | L25: =Mensuel!$C$27 -> 540 | M25: =323+65+72 -> 460 | N25: =Mensuel!$C$27 -> 540 | O25: 357 | P25: =Mensuel!$C$27 -> 540 | R25: =Mensuel!$C$27 -> 540 | S25: =Mensuel!$C$27 -> 540 | T25: =Mensuel!$C$27 -> 540 | U25: =Mensuel!$C$27 -> 540 | W25: =SUM(B25,D25,F25,H25,J25,L25,N25,P25,R25,S25,T25,U25) -> 6480 | X25: =SUM(E25,G25,I25,K25,M25,O25,Q25) -> 2826.12
A26: Entretien | E26: =250+636.71 -> 886.71 | H26: =120+130 -> 250 | I26: =117+134 -> 251 | X26: =SUM(E26,G26,I26,K26,M26,O26,Q26) -> 1137.71
A28: FINANCE | B28: =SUM(B29:B33) -> 428.17 | C28: =sum(C29:C33) -> 287.17 | D28: =SUM(D29:D33) -> 428.17 | E28: =SUM(E29:E33) -> 324.48 | F28: =SUM(F29:F33) -> 428.17 | G28: =sum(G29:G33) -> 922.07 | H28: =SUM(H29:H33) -> 728.17 | I28: =sum(I29:I33) -> 690.07 | J28: =SUM(J29:J33) -> 628.17 | K28: =sum(K29:K33) -> 1599.32 | L28: =SUM(L29:L33) -> 628.17 | M28: =sum(M29:M33) -> 1561.98 | N28: =SUM(N29:N33) -> 628.17 | O28: =sum(O29:O33) -> 1595.73 | P28: =SUM(P29:P33) -> 628.17 | Q28: =sum(Q29:Q33) -> 195.17 | R28: =SUM(R29:R33) -> 628.17 | S28: =SUM(S29:S33) -> 628.17 | T28: =SUM(T29:T33) -> 628.17 | U28: =SUM(U29:U33) -> 628.17 | W28: =SUM(W29:W33) -> 7038.04 | X28: =SUM(X29:X33) -> 6888.82
A29: Frais comptes | B29: =Mensuel!$G$22 -> 40 | C29: 40 | D29: =Mensuel!$G$22 -> 40 | E29: =10.75+3.95+9.61 -> 24.31 | F29: =Mensuel!$G$22 -> 40 | G29: =3.95+10.95 -> 14.9 | H29: =Mensuel!$G$22 -> 40 | I29: =3.95+10.95 -> 14.9 | J29: =Mensuel!$G$22 -> 40 | K29: =3.95+10.95 -> 14.9 | L29: =Mensuel!$G$22 -> 40 | M29: =10.95+9.61 -> 20.56 | N29: =Mensuel!$G$22 -> 40 | O29: =10.95+9.61 -> 20.56 | P29: =Mensuel!$G$22 -> 40 | R29: =Mensuel!$G$22 -> 40 | S29: =Mensuel!$G$22 -> 40 | T29: =Mensuel!$G$22 -> 40 | U29: =Mensuel!$G$22 -> 40 | W29: =SUM(B29,D29,F29,H29,J29,L29,N29,P29,R29,S29,T29,U29) -> 480 | X29: =SUM(E29,G29,I29,K29,M29,O29,Q29) -> 110.13
A30: Garderie | H30: 300 | I30: 300 | J30: =Mensuel!$O$15 -> 200 | K30: 1200 | L30: =Mensuel!$O$15 -> 200 | M30: =300*4 -> 1200 | N30: =Mensuel!$O$15 -> 200 | O30: 1200 | P30: =Mensuel!$O$15 -> 200 | R30: =Mensuel!$O$15 -> 200 | S30: =Mensuel!$O$15 -> 200 | T30: =Mensuel!$O$15 -> 200 | U30: =Mensuel!$O$15 -> 200 | W30: =SUM(B30,D30,F30,H30,J30,L30,N30,P30,R30,S30,T30,U30) -> 1900 | X30: =SUM(E30,G30,I30,K30,M30,O30,Q30) -> 3900
A31: Kaleido | B31: =Mensuel!$K$26 -> 62.17 | C31: 61.17 | D31: =Mensuel!$K$26 -> 62.17 | E31: 61.17 | F31: =Mensuel!$K$26 -> 62.17 | G31: 61.17 | H31: =Mensuel!$K$26 -> 62.17 | I31: 61.17 | J31: =Mensuel!$K$26 -> 62.17 | K31: 61.17 | L31: =Mensuel!$K$26 -> 62.17 | M31: 61.17 | N31: =Mensuel!$K$26 -> 62.17 | O31: 61.17 | P31: =Mensuel!$K$26 -> 62.17 | Q31: 61.17 | R31: =Mensuel!$K$26 -> 62.17 | S31: =Mensuel!$K$26 -> 62.17 | T31: =Mensuel!$K$26 -> 62.17 | U31: =Mensuel!$K$26 -> 62.17 | W31: =SUM(B31,D31,F31,H31,J31,L31,N31,P31,R31,S31,T31,U31) -> 746.04 | X31: =SUM(E31,G31,I31,K31,M31,O31,Q31) -> 428.19
A32: Service de garde | B32: =Mensuel!$O$17 -> 180 | C32: 40 | D32: =Mensuel!$O$17 -> 180 | E32: =40+65 -> 105 | F32: =Mensuel!$O$17 -> 180 | G32: =684+28 -> 712 | H32: =Mensuel!$O$17 -> 180 | I32: 180 | J32: 180 | K32: 189.25 | L32: 180 | M32: 146.25 | N32: 180 | O32: 180 | P32: 180 | R32: 180 | S32: 180 | T32: 180 | U32: 180 | W32: =SUM(B32,D32,F32,H32,J32,L32,N32,P32,R32,S32,T32,U32) -> 2160 | X32: =SUM(E32,G32,I32,K32,M32,O32,Q32) -> 1512.5
A33: Ass. Vie | B33: =Mensuel!$C$23+Mensuel!$C$24 -> 146 | C33: 146 | D33: =Mensuel!$C$23+Mensuel!$C$24 -> 146 | E33: 134 | F33: =Mensuel!$C$23+Mensuel!$C$24 -> 146 | G33: 134 | H33: =Mensuel!$C$23+Mensuel!$C$24 -> 146 | I33: 134 | J33: =Mensuel!$C$23+Mensuel!$C$24 -> 146 | K33: 134 | L33: =Mensuel!$C$23+Mensuel!$C$24 -> 146 | M33: 134 | N33: =Mensuel!$C$23+Mensuel!$C$24 -> 146 | O33: 134 | P33: =Mensuel!$C$23+Mensuel!$C$24 -> 146 | Q33: 134 | R33: =Mensuel!$C$23+Mensuel!$C$24 -> 146 | S33: =Mensuel!$C$23+Mensuel!$C$24 -> 146 | T33: =Mensuel!$C$23+Mensuel!$C$24 -> 146 | U33: =Mensuel!$C$23+Mensuel!$C$24 -> 146 | W33: =SUM(B33,D33,F33,H33,J33,L33,N33,P33,R33,S33,T33,U33) -> 1752 | X33: =SUM(E33,G33,I33,K33,M33,O33,Q33) -> 938
A34: Orthodonthie | S34: =Mensuel!$K$20 -> 175 | T34: =Mensuel!$K$20 -> 175 | U34: =Mensuel!$K$20 -> 175
A36: NOURRITURE | B36: =SUM(B37:B39) -> 1058.3333 | C36: =sum(C37:C39) -> 1018.3333 | D36: =SUM(D37:D39) -> 1058.3333 | E36: =SUM(E37:E39) -> 939.49 | F36: =SUM(F37:F39) -> 1058.3333 | G36: =sum(G37:G39) -> 1233.27 | H36: =SUM(H37:H39) -> 1058.3333 | I36: =sum(I37:I39) -> 1149.99 | J36: =SUM(J37:J39) -> 1058.3333 | K36: =sum(K37:K39) -> 1251.43 | L36: =SUM(L37:L39) -> 1058.3333 | M36: =sum(M37:M39) -> 1110.5 | N36: =SUM(N37:N39) -> 1058.3333 | O36: =sum(O37:O39) -> 940.26 | P36: =SUM(P37:P39) -> 1058.3333 | Q36: =sum(Q37:Q39) -> 0 | R36: =SUM(R37:R39) -> 1058.3333 | S36: =SUM(S37:S39) -> 1058.3333 | T36: =SUM(T37:T39) -> 1058.3333 | U36: =SUM(U37:U39) -> 1058.3333 | W36: =SUM(W37:W39) -> 12700 | X36: =SUM(X37:X39) -> 6624.94
A37: Épicerie | B37: =Mensuel!$G$24+Mensuel!$O$19 -> 848.33333 | C37: 808.33333 | D37: =Mensuel!$G$24+Mensuel!$O$19 -> 848.33333 | E37: 675 | F37: =Mensuel!$G$24+Mensuel!$O$19 -> 848.33333 | G37: =22.99+43.12+111.24+8.32+80.46+7.19+122.37+29.03+20.09+19.16+93.72+36.5+124.47+9.51+4.97+62.7+94.08+2.52+11.87 -> 904.31 | H37: =Mensuel!$G$24+Mensuel!$O$19 -> 848.33333 | I37: 919.2 | J37: =Mensuel!$G$24+Mensuel!$O$19 -> 848.33333 | K37: =965.86 -> 965.86 | L37: =Mensuel!$G$24+Mensuel!$O$19 -> 848.33333 | M37: =463.23+40.1+23.99+93.2+10.49+141.24+8.61+35.8+7.27 -> 823.93 | N37: =Mensuel!$G$24+Mensuel!$O$19 -> 848.33333 | O37: =598.15+115 -> 713.15 | P37: =Mensuel!$G$24+Mensuel!$O$19 -> 848.33333 | R37: =Mensuel!$G$24+Mensuel!$O$19 -> 848.33333 | S37: =Mensuel!$G$24+Mensuel!$O$19 -> 848.33333 | T37: =Mensuel!$G$24+Mensuel!$O$19 -> 848.33333 | U37: =Mensuel!$G$24+Mensuel!$O$19 -> 848.33333 | W37: =SUM(B37,D37,F37,H37,J37,L37,N37,P37,R37,S37,T37,U37) -> 10180 | X37: =SUM(E37,G37,I37,K37,M37,O37,Q37) -> 5001.45
A38: Restaurant | B38: =Mensuel!$K$17 -> 100 | C38: 100 | D38: =Mensuel!$K$17 -> 100 | E38: =5.33+21.13+8.03 -> 34.49 | F38: =Mensuel!$K$17 -> 100 | G38: =92.82+11.78+17.73+6.88+24.35+6.99+21.83+50.9 -> 233.28 | H38: =Mensuel!$K$17 -> 100 | I38: 58.37 | J38: =Mensuel!$K$17 -> 100 | K38: 230.47 | L38: =Mensuel!$K$17 -> 100 | M38: =168.23+21.13+16 -> 205.36 | N38: =Mensuel!$K$17 -> 100 | O38: =138.41+29 -> 167.41 | P38: =Mensuel!$K$17 -> 100 | R38: =Mensuel!$K$17 -> 100 | S38: =Mensuel!$K$17 -> 100 | T38: =Mensuel!$K$17 -> 100 | U38: =Mensuel!$K$17 -> 100 | W38: =SUM(B38,D38,F38,H38,J38,L38,N38,P38,R38,S38,T38,U38) -> 1200 | X38: =SUM(E38,G38,I38,K38,M38,O38,Q38) -> 929.38
A39: Pharmacie | B39: =Mensuel!$G$26 -> 110 | C39: 110 | D39: =Mensuel!$G$26 -> 110 | E39: =38.42+48.82+36.17+63.69+20.67+22.23 -> 230 | F39: =Mensuel!$G$26 -> 110 | G39: =13.44+21.24+11.63+31.56+17.81 -> 95.68 | H39: =Mensuel!$G$26 -> 110 | I39: 172.42 | J39: =Mensuel!$G$26 -> 110 | K39: 55.1 | L39: =Mensuel!$G$26 -> 110 | M39: 81.21 | N39: =Mensuel!$G$26 -> 110 | O39: 59.7 | P39: =Mensuel!$G$26 -> 110 | R39: =Mensuel!$G$26 -> 110 | S39: =Mensuel!$G$26 -> 110 | T39: =Mensuel!$G$26 -> 110 | U39: =Mensuel!$G$26 -> 110 | W39: =SUM(B39,D39,F39,H39,J39,L39,N39,P39,R39,S39,T39,U39) -> 1320 | X39: =SUM(E39,G39,I39,K39,M39,O39,Q39) -> 694.11
A41: ABONNEMENTS | B41: =SUM(B42:B46) -> 186.38 | C41: =sum(C42:C46) -> 165.93 | D41: =SUM(D42:D46) -> 186.38 | E41: =SUM(E42:E46) -> 166.72 | F41: =SUM(F42:F46) -> 186.38 | G41: =sum(G42:G46) -> 166.72 | H41: =SUM(H42:H46) -> 186.38 | I41: =sum(I42:I46) -> 165.93 | J41: =SUM(J42:J46) -> 186.38 | K41: =sum(K42:K46) -> 165.93 | L41: =SUM(L42:L46) -> 186.38 | M41: =sum(M42:M46) -> 165.93 | N41: =SUM(N42:N46) -> 186.38 | O41: =sum(O42:O46) -> 165.93 | P41: =SUM(P42:P46) -> 186.38 | Q41: =sum(Q42:Q46) -> 165.93 | R41: =SUM(R42:R46) -> 186.38 | S41: =SUM(S42:S46) -> 158.71 | T41: =SUM(T42:T46) -> 158.71 | U41: =SUM(U42:U46) -> 158.71 | W41: =SUM(W42:W46) -> 2153.55 | X41: =SUM(X42:X46) -> 1163.09
A42: Spotify | B42: =Mensuel!$G$16 -> 24.13 | C42: 19.53 | D42: =Mensuel!$G$16 -> 24.13 | E42: 19.53 | F42: =Mensuel!$G$16 -> 24.13 | G42: 19.53 | H42: =Mensuel!$G$16 -> 24.13 | I42: 19.53 | J42: =Mensuel!$G$16 -> 24.13 | K42: 19.53 | L42: =Mensuel!$G$16 -> 24.13 | M42: 19.53 | N42: =Mensuel!$G$16 -> 24.13 | O42: 19.53 | P42: =Mensuel!$G$16 -> 24.13 | Q42: 19.53 | R42: =Mensuel!$G$16 -> 24.13 | S42: =Mensuel!$G$16 -> 24.13 | T42: =Mensuel!$G$16 -> 24.13 | U42: =Mensuel!$G$16 -> 24.13 | W42: =SUM(B42,D42,F42,H42,J42,L42,N42,P42,R42,S42,T42,U42) -> 289.56 | X42: =SUM(E42,G42,I42,K42,M42,O42,Q42) -> 136.71
A43: Netflix | B43: =Mensuel!$G$17 -> 31.02 | C43: 18.96 | D43: =Mensuel!$G$17 -> 31.02 | E43: 18.96 | F43: =Mensuel!$G$17 -> 31.02 | G43: 18.96 | H43: =Mensuel!$G$17 -> 31.02 | I43: 18.96 | J43: =Mensuel!$G$17 -> 31.02 | K43: 18.96 | L43: =Mensuel!$G$17 -> 31.02 | M43: 18.96 | N43: =Mensuel!$G$17 -> 31.02 | O43: 18.96 | P43: =Mensuel!$G$17 -> 31.02 | Q43: 18.96 | R43: =Mensuel!$G$17 -> 31.02 | S43: =Mensuel!$G$17 -> 31.02 | T43: =Mensuel!$G$17 -> 31.02 | U43: =Mensuel!$G$17 -> 31.02 | W43: =SUM(B43,D43,F43,H43,J43,L43,N43,P43,R43,S43,T43,U43) -> 372.24 | X43: =SUM(E43,G43,I43,K43,M43,O43,Q43) -> 132.72
A44: Amazon | B44: =Mensuel!$G$19 -> 11.49 | C44: 11.49 | D44: =Mensuel!$G$19 -> 11.49 | E44: 11.49 | F44: =Mensuel!$G$19 -> 11.49 | G44: 11.49 | H44: =Mensuel!$G$19 -> 11.49 | I44: 11.49 | J44: =Mensuel!$G$19 -> 11.49 | K44: 11.49 | L44: =Mensuel!$G$19 -> 11.49 | M44: 11.49 | N44: =Mensuel!$G$19 -> 11.49 | O44: 11.49 | P44: =Mensuel!$G$19 -> 11.49 | Q44: 11.49 | R44: =Mensuel!$G$19 -> 11.49 | S44: =Mensuel!$G$19 -> 11.49 | T44: =Mensuel!$G$19 -> 11.49 | U44: =Mensuel!$G$19 -> 11.49 | W44: =SUM(B44,D44,F44,H44,J44,L44,N44,P44,R44,S44,T44,U44) -> 137.88 | X44: =SUM(E44,G44,I44,K44,M44,O44,Q44) -> 80.43
A45: Fizz | B45: 112.74 | C45: 112.74 | D45: 112.74 | E45: =30.5+31.65+50.59 -> 112.74 | F45: 112.74 | G45: 112.74 | H45: 112.74 | I45: =30.5+31.65+50.59 -> 112.74 | J45: 112.74 | K45: =30.5+31.65+50.59 -> 112.74 | L45: 112.74 | M45: =30.5+31.65+50.59 -> 112.74 | N45: 112.74 | O45: =30.5+31.65+50.59 -> 112.74 | P45: 112.74 | Q45: =30.5+31.65+50.59 -> 112.74 | R45: 112.74 | S45: =Mensuel!$K$15 -> 85.07 | T45: =Mensuel!$K$15 -> 85.07 | U45: =Mensuel!$K$15 -> 85.07 | W45: =SUM(B45,D45,F45,H45,J45,L45,N45,P45,R45,S45,T45,U45) -> 1269.87 | X45: =SUM(E45,G45,I45,K45,M45,O45,Q45) -> 789.18
A46: Apple+Google | B46: =Mensuel!$G$18 -> 7 | C46: 3.21 | D46: =Mensuel!$G$18 -> 7 | E46: =3.21+0.79 -> 4 | F46: =Mensuel!$G$18 -> 7 | G46: 4 | H46: =Mensuel!$G$18 -> 7 | I46: 3.21 | J46: =Mensuel!$G$18 -> 7 | K46: 3.21 | L46: =Mensuel!$G$18 -> 7 | M46: 3.21 | N46: =Mensuel!$G$18 -> 7 | O46: 3.21 | P46: =Mensuel!$G$18 -> 7 | Q46: 3.21 | R46: =Mensuel!$G$18 -> 7 | S46: =Mensuel!$G$18 -> 7 | T46: =Mensuel!$G$18 -> 7 | U46: =Mensuel!$G$18 -> 7 | W46: =SUM(B46,D46,F46,H46,J46,L46,N46,P46,R46,S46,T46,U46) -> 84 | X46: =SUM(E46,G46,I46,K46,M46,O46,Q46) -> 24.05
A48: Autre | B48: =SUM(B49:B75) -> 213 | C48: =SUM(C49:C75) -> 213 | D48: =SUM(D49:D75) -> 533 | E48: =SUM(E49:E60) -> 1106.56 | F48: =SUM(F49:F75) -> 853 | G48: =SUM(G49:G75) -> 3702.11 | H48: =SUM(H49:H75) -> 1515 | I48: =SUM(I49:I75) -> 1860.41 | J48: =SUM(J49:J75) -> 652.08 | K48: =SUM(K49:K75) -> 1216.02 | L48: =SUM(L49:L75) -> 218 | M48: =SUM(M49:M75) -> 968.47 | ... U48: =SUM(U49:U75) -> 0 | W48: =SUM(W49:W59) -> 7728.64 | X48: =SUM(X49:X59) -> 8834.46
...

Sheet Suivi par mois
C1: 43739 | F1: 43770 | I1: 43800 | L1: 43831 | O1: 43863
A2: INCOME | C2: Budget | D2: Actual | E2: Dif | F2: Budget | G2: Actual | H2: Dif | I2: Budget | J2: Actual | K2: Dif | L2: Budget | M2: Actual | N2: Dif | O2: Budget | P2: Actual | Q2: Dif
B3: Eric | C3: 3276.28 | D3: 3939 | E3: =D3-C3 -> 662.72 | F3: 3276.28 | G3: 3276.28 | H3: =G3-F3 -> 0 | I3: 3276.28 | J3: 3308.34 | K3: =J3-I3 -> 32.06 | L3: 3276.28 | M3: =818.3*4 -> 3273.2 | N3: =M3-L3 -> -3.08 | O3: ='Budget Courant'!$C5 -> 3673.32 | P3: 3276.2 | Q3: =P3-O3 -> -397.12
B4: Maryse | C4: 1404 | D4: 1313 | E4: =D4-C4 -> -91 | F4: 1304 | G4: 0 | H4: =G4-F4 -> -1304 | I4: 1304 | J4: 0 | K4: =J4-I4 -> -1304 | L4: 1304 | M4: 1956 | N4: =M4-L4 -> 652 | O4: ='Budget Courant'!$C6 -> 2123 | P4: 1308 | Q4: =P4-O4 -> -815
B5: Gouv | C5: 330 | D5: 330 | E5: =D5-C5 -> 0 | F5: 330 | G5: 330 | H5: =G5-F5 -> 0 | I5: 330 | J5: 0 | K5: =J5-I5 -> -330 | L5: 330 | M5: 630 | N5: =M5-L5 -> 300 | O5: ='Budget Courant'!$C8 -> 300 | P5: 0 | Q5: =P5-O5 -> -300
B6: Garderie | C6: 445.1 | D6: 445.1 | E6: =D6-C6 -> 0 | F6: 445.1 | G6: 445.1 | H6: =G6-F6 -> 0 | I6: 445.1 | J6: 445.1 | K6: =J6-I6 -> 0 | L6: 409.6 | M6: 409.6 | N6: =M6-L6 -> 0 | O6: ='Budget Courant'!$C7 | P6: 409.6 | Q6: =P6-O6 -> 409.6
B7: Other | E7: =D7-C7 -> 0 | G7: =803.5+476+1000+100 -> 2379.5 | H7: =G7-F7 -> 2379.5 | J7: =985+476 -> 1461 | K7: =J7-I7 -> 1461 | M7: 480 | N7: =M7-L7 -> 480 | P7: 146 | Q7: =P7-O7 -> 146
B8: Total | C8: =SUM(C3:C7) -> 5455.38 | D8: =SUM(D3:D7) -> 6027.1 | E8: =D8-C8 -> 571.72 | F8: =SUM(F3:F7) -> 5355.38 | G8: =SUM(G3:G7) -> 6430.88 | H8: =G8-F8 -> 1075.5 | I8: =SUM(I3:I7) -> 5355.38 | J8: =SUM(J3:J7) -> 5214.44 | K8: =J8-I8 -> -140.94 | L8: =SUM(L3:L7) -> 5319.88 | M8: =SUM(M3:M7) -> 6748.8 | N8: =M8-L8 -> 1428.92 | O8: =SUM(O3:O7) -> 6096.32 | P8: =SUM(P3:P7) -> 5139.8 | Q8: =P8-O8 -> -956.52
A9: EXPENSES
B10: Maison | C10: 1025.08 | D10: 1025.08 | E10: =C10-D10 -> 0 | F10: 1025.08 | G10: 1025.08 | H10: =if(ISNUMBER(G10), F10-G10,"TBD") -> 0 | I10: 1025.08 | J10: 1015 | K10: =if(ISNUMBER(J10), I10-J10,"TBD") -> 10.08 | L10: 1025.08 | M10: 1025 | N10: =if(ISNUMBER(M10), L10-M10,"TBD") -> 0.08 | O10: ='Budget Courant'!$C13 -> 1043.33 | P10: 1014 | Q10: =if(ISNUMBER(P10), O10-P10,"TBD") -> 29.33
B11: Assurance | C11: 143.23 | D11: 143.23 | E11: =C11-D11 -> 0 | F11: 143.23 | G11: 143.23 | H11: =if(ISNUMBER(G11), F11-G11,"TBD") -> 0 | I11: 143.23 | J11: 150.51 | K11: =if(ISNUMBER(J11), I11-J11,"TBD") -> -7.28 | L11: 143.23 | M11: =126.92+32.42 -> 159.34 | N11: =if(ISNUMBER(M11), L11-M11,"TBD") -> -16.11 | O11: ='Budget Courant'!$C17 -> 181.1 | P11: =127.09+32.42 -> 159.51 | Q11: =if(ISNUMBER(P11), O11-P11,"TBD") -> 21.59
B12: Paiement Auto | C12: 706.6 | D12: 1028.15 | E12: =C12-D12 -> -321.55 | F12: 706.6 | G12: 706.6 | H12: =if(ISNUMBER(G12), F12-G12,"TBD") -> 0 | I12: 706.6 | J12: 706.6 | K12: =if(ISNUMBER(J12), I12-J12,"TBD") -> 0 | L12: 706.6 | M12: 921.27 | N12: =if(ISNUMBER(M12), L12-M12,"TBD") -> -214.67 | O12: ='Budget Courant'!$C23+#REF! -> #REF! | P12: =214.67+214.67+277.26 -> 706.6 | Q12: =if(ISNUMBER(P12), O12-P12,"TBD") -> #REF!
B13: Videotron | C13: 148.73 | D13: 148.73 | E13: =C13-D13 -> 0 | F13: 148.73 | G13: 148.73 | H13: =if(ISNUMBER(G13), F13-G13,"TBD") -> 0 | I13: 148.73 | J13: 170.78 | K13: =if(ISNUMBER(J13), I13-J13,"TBD") -> -22.05 | L13: 148.73 | M13: 148.73 | N13: =if(ISNUMBER(M13), L13-M13,"TBD") -> 0 | O13: ='Budget Courant'!$K13 -> 175.23 | P13: 148.73 | Q13: =if(ISNUMBER(P13), O13-P13,"TBD") -> 26.5
B14: Koodo | C14: 65.36 | D14: 65.36 | E14: =C14-D14 -> 0 | F14: 65.36 | G14: 0 | H14: =if(ISNUMBER(G14), F14-G14,"TBD") -> 65.36 | I14: 79.86 | J14: 156.84 | K14: =if(ISNUMBER(J14), I14-J14,"TBD") -> -76.98 | L14: 79.86 | M14: 79.86 | N14: =if(ISNUMBER(M14), L14-M14,"TBD") -> 0 | O14: ='Budget Courant'!$K15 -> 62.64 | P14: 306.31 | Q14: =if(ISNUMBER(P14), O14-P14,"TBD") -> -243.67
B15: Pret | C15: 155.64 | D15: 155.64 | E15: =C15-D15 -> 0 | F15: 155.64 | G15: 155.64 | H15: =if(ISNUMBER(G15), F15-G15,"TBD") -> 0 | I15: 155.64 | J15: 155.64 | K15: =if(ISNUMBER(J15), I15-J15,"TBD") -> 0 | L15: 155.64 | M15: =118.01+37.63 -> 155.64 | N15: =if(ISNUMBER(M15), L15-M15,"TBD") -> 0 | O15: ='Budget Courant'!$G13 -> 118.01 | P15: 118.01 | Q15: =if(ISNUMBER(P15), O15-P15,"TBD") -> 0
B16: Abonnements | C16: 34.95 | D16: 34.95 | E16: =C16-D16 -> 0 | F16: 34.95 | G16: 34.95 | H16: =if(ISNUMBER(G16), F16-G16,"TBD") -> 0 | I16: 34.95 | J16: 34.95 | K16: =if(ISNUMBER(J16), I16-J16,"TBD") -> 0 | L16: 34.95 | M16: 34.95 | N16: =if(ISNUMBER(M16), L16-M16,"TBD") -> 0 | O16: ='Budget Courant'!$G16 -> 67.79 | P16: =3.07+15.39+16.49 -> 34.95 | Q16: =if(ISNUMBER(P16), O16-P16,"TBD") -> 32.84
B17: Universitas | C17: 31.02 | D17: 31.02 | E17: =C17-D17 -> 0 | F17: 31.02 | G17: 31.02 | H17: =if(ISNUMBER(G17), F17-G17,"TBD") -> 0 | I17: 31.02 | J17: 31.02 | K17: =if(ISNUMBER(J17), I17-J17,"TBD") -> 0 | L17: 31.02 | M17: 31.02 | N17: =if(ISNUMBER(M17), L17-M17,"TBD") -> 0 | O17: ='Budget Courant'!$O15 -> 31.02 | P17: 31.02 | Q17: =if(ISNUMBER(P17), O17-P17,"TBD") -> 0
B18: Garderie | C18: 680 | D18: 680 | E18: =C18-D18 -> 0 | F18: 680 | G18: 680 | H18: =if(ISNUMBER(G18), F18-G18,"TBD") -> 0 | I18: 680 | J18: 680 | K18: =if(ISNUMBER(J18), I18-J18,"TBD") -> 0 | L18: 680 | M18: =160*5 -> 800 | N18: =if(ISNUMBER(M18), L18-M18,"TBD") -> -120 | O18: ='Budget Courant'!$O19 -> 170 | P18: =(160*4)-64 -> 576 | Q18: =if(ISNUMBER(P18), O18-P18,"TBD") -> -406
B19: Plaque/Permis | C19: 40 | D19: 0 | E19: =C19-D19 -> 40 | F19: 40 | G19: 40 | H19: =if(ISNUMBER(G19), F19-G19,"TBD") -> 0 | I19: 40 | J19: 40 | K19: =if(ISNUMBER(J19), I19-J19,"TBD") -> 0 | L19: 40 | M19: 40 | N19: =if(ISNUMBER(M19), L19-M19,"TBD") -> 0 | O19: ='Budget Courant'!$C25+'Budget Courant'!$C26 -> 45 | P19: 227.57 | Q19: =if(ISNUMBER(P19), O19-P19,"TBD") -> -182.57
B20: Gas | C20: 400 | D20: 321.55 | E20: =C20-D20 -> 78.45 | F20: 400 | G20: 349.01 | H20: =if(ISNUMBER(G20), F20-G20,"TBD") -> 50.99 | I20: 400 | J20: 388.33 | K20: =if(ISNUMBER(J20), I20-J20,"TBD") -> 11.67 | L20: 400 | M20: 352.36 | N20: =if(ISNUMBER(M20), L20-M20,"TBD") -> 47.64 | O20: ='Budget Courant'!$C24 -> 400 | P20: 265.23 | Q20: =if(ISNUMBER(P20), O20-P20,"TBD") -> 134.77
B21: Finance | C21: 40 | D21: 38.79 | E21: =C21-D21 -> 1.21 | F21: 40 | G21: 51.16 | H21: =if(ISNUMBER(G21), F21-G21,"TBD") -> -11.16 | I21: 40 | J21: 30.21 | K21: =if(ISNUMBER(J21), I21-J21,"TBD") -> 9.79 | L21: 40 | M21: =13.38+17.44 -> 30.82 | N21: =if(ISNUMBER(M21), L21-M21,"TBD") -> 9.18 | O21: ='Budget Courant'!$G23 -> 40 | P21: 35.64 | Q21: =if(ISNUMBER(P21), O21-P21,"TBD") -> 4.36
B22: Epicerie | C22: 600 | D22: 526.02 | E22: =C22-D22 -> 73.98 | F22: 600 | G22: 516.99 | H22: =if(ISNUMBER(G22), F22-G22,"TBD") -> 83.01 | I22: 600 | J22: 659.96 | K22: =if(ISNUMBER(J22), I22-J22,"TBD") -> -59.96 | L22: 600 | M22: 291.28 | N22: =if(ISNUMBER(M22), L22-M22,"TBD") -> 308.72 | O22: ='Budget Courant'!$G25 -> 600 | P22: 387.47 | Q22: =if(ISNUMBER(P22), O22-P22,"TBD") -> 212.53
B23: Restaurants | C23: 100 | D23: 424.47 | E23: =C23-D23 -> -324.47 | F23: 100 | G23: 242.13 | H23: =if(ISNUMBER(G23), F23-G23,"TBD") -> -142.13 | I23: 100 | J23: 115.43 | K23: =if(ISNUMBER(J23), I23-J23,"TBD") -> -15.43 | L23: 100 | M23: 149.31 | N23: =if(ISNUMBER(M23), L23-M23,"TBD") -> -49.31 | O23: ='Budget Courant'!$K17 -> 200 | P23: =94.05+56.24+19.55+5.1 -> 174.94 | Q23: =if(ISNUMBER(P23), O23-P23,"TBD") -> 25.06
B24: Alcool | C24: 50 | D24: 179.36 | E24: =C24-D24 -> -129.36 | F24: 50 | G24: 44.28 | H24: =if(ISNUMBER(G24), F24-G24,"TBD") -> 5.72 | I24: 50 | J24: 73.15 | K24: =if(ISNUMBER(J24), I24-J24,"TBD") -> -23.15 | L24: 50 | M24: 8.9 | N24: =if(ISNUMBER(M24), L24-M24,"TBD") -> 41.1 | O24: ='Budget Courant'!$O21 -> 100 | P24: 36.1 | Q24: =if(ISNUMBER(P24), O24-P24,"TBD") -> 63.9
B25: Pharmacie | C25: 60 | D25: 154.88 | E25: =C25-D25 -> -94.88 | F25: 60 | G25: 28.96 | H25: =if(ISNUMBER(G25), F25-G25,"TBD") -> 31.04 | I25: 60 | J25: 120.1 | K25: =if(ISNUMBER(J25), I25-J25,"TBD") -> -60.1 | L25: 60 | M25: 22.91 | N25: =if(ISNUMBER(M25), L25-M25,"TBD") -> 37.09 | O25: ='Budget Courant'!$G27 -> 60 | P25: 47.33 | Q25: =if(ISNUMBER(P25), O25-P25,"TBD") -> 12.67
B26: Animaux | C26: 100 | D26: 125.24 | E26: =C26-D26 -> -25.24 | F26: 30 | G26: 48.85 | H26: =if(ISNUMBER(G26), F26-G26,"TBD") -> -18.85 | I26: 30 | J26: 30 | K26: =if(ISNUMBER(J26), I26-J26,"TBD") -> 0 | L26: 30 | M26: 131.56 | N26: =if(ISNUMBER(M26), L26-M26,"TBD") -> -101.56 | O26: ='Budget Courant'!$O13 -> 50 | P26: 49.58 | Q26: =if(ISNUMBER(P26), O26-P26,"TBD") -> 0.42
B27: Dentiste | C27: ='Budget Courant'!$K19 -> 30 | D27: 0 | E27: =C27-D27 -> 30 | F27: 30 | G27: 177 | H27: =if(ISNUMBER(G27), F27-G27,"TBD") -> -147 | I27: 30 | J27: 30 | K27: =if(ISNUMBER(J27), I27-J27,"TBD") -> 0 | L27: 30 | M27: 30 | N27: =if(ISNUMBER(M27), L27-M27,"TBD") -> 0 | O27: ='Budget Courant'!$K19 -> 30 | P27: 30 | Q27: =if(ISNUMBER(P27), O27-P27,"TBD") -> 0
B28: RAMQ | C28: 100 | D28: 0 | E28: =C28-D28 -> 100 | F28: 100 | G28: 100 | H28: =if(ISNUMBER(G28), F28-G28,"TBD") -> 0 | I28: 100 | J28: 100 | K28: =if(ISNUMBER(J28), I28-J28,"TBD") -> 0 | L28: 100 | M28: 100 | N28: =if(ISNUMBER(M28), L28-M28,"TBD") -> 0 | O28: ='Budget Courant'!$O17 -> 25 | P28: 100 | Q28: =if(ISNUMBER(P28), O28-P28,"TBD") -> -75
B29: Autre 1 | D29: 191 | E29: =C29-D29 -> -191 | G29: 77.44 | H29: =if(ISNUMBER(G29), F29-G29,"TBD") -> -77.44 | J29: 17 | K29: =if(ISNUMBER(J29), I29-J29,"TBD") -> -17 | M29: =86.34 -> 86.34 | N29: =if(ISNUMBER(M29), L29-M29,"TBD") -> -86.34 | P29: =41.8+10.93+38.63 -> 91.36 | Q29: =if(ISNUMBER(P29), O29-P29,"TBD") -> -91.36
B30: Autre 2 | D30: 165 | E30: =C30-D30 -> -165 | G30: 25 | H30: =if(ISNUMBER(G30), F30-G30,"TBD") -> -25 | J30: 31.37 | K30: =if(ISNUMBER(J30), I30-J30,"TBD") -> -31.37 | M30: 545.25 | N30: =if(ISNUMBER(M30), L30-M30,"TBD") -> -545.25 | P30: =18+70 -> 88 | Q30: =if(ISNUMBER(P30), O30-P30,"TBD") -> -88
B31: Autre 3 | G31: 122.39 | H31: =if(ISNUMBER(G31), F31-G31,"TBD") -> -122.39 | J31: 120.76 | K31: =if(ISNUMBER(J31), I31-J31,"TBD") -> -120.76 | M31: =28+85+65 -> 178 | N31: =if(ISNUMBER(M31), L31-M31,"TBD") -> -178 | P31: 11.48 | Q31: =if(ISNUMBER(P31), O31-P31,"TBD") -> -11.48
B32: Autre 4 | G32: 20.47 | H32: =if(ISNUMBER(G32), F32-G32,"TBD") -> -20.47 | J32: 20.67 | K32: =if(ISNUMBER(J32), I32-J32,"TBD") -> -20.67 | M32: 85.15 | N32: =if(ISNUMBER(M32), L32-M32,"TBD") -> -85.15 | P32: 4.59 | Q32: =if(ISNUMBER(P32), O32-P32,"TBD") -> -4.59
B33: Autre 5 | G33: 215.13 | H33: =if(ISNUMBER(G33), F33-G33,"TBD") -> -215.13 | K33: =if(ISNUMBER(J33), I33-J33,"TBD") -> TBD | N33: =if(ISNUMBER(M33), L33-M33,"TBD") -> TBD | P33: 27 | Q33: =if(ISNUMBER(P33), O33-P33,"TBD") -> -27
B34: Total | C34: =SUM(C10:C30) -> 4510.61 | D34: =SUM(D10:D30) -> 5438.47 | E34: =SUM(E10:E30) -> -927.86 | F34: =SUM(F10:F30) -> 4440.61 | G34: =SUM(G10:G33) -> 4984.06 | H34: {=if(ISNUMBER(G34),SUM(H10:H33),"TBD")} -> -543.45 | I34: =SUM(I10:I30) -> 4455.11 | J34: =SUM(J10:J33) -> 4878.32 | K34: {=if(ISNUMBER(J34),SUM(K10:K33),"TBD")} -> -423.21 | L34: =SUM(L10:L30) -> 4455.11 | M34: =SUM(M10:M33) -> 5407.69 | N34: {=if(ISNUMBER(M34),SUM(N10:N33),"TBD")} -> -952.58 | O34: =SUM(O10:O30) -> #REF! | P34: =SUM(P10:P33) -> 4671.42 | Q34: {=if(ISNUMBER(P34),SUM(Q10:Q33),"TBD")} -> #REF!
A36: Difference | B36: - | C36: =D8-D34 -> 588.63 | F36: =G8-G34 -> 1446.82 | I36: =if(isnumber(K34),J8-J34, "TBD") -> 336.12 | L36: =if(isnumber(N34),M8-M34, "TBD") -> 1341.11 | O36: =if(isnumber(Q34),P8-P34, "TBD") -> TBD
J38: Bal Jan 12 2020 | K38: 1981.52 | O38: after Visa (03-08) | Q38: 3508.65
J39: after all payments

Sheet 2023
A1: 2023 | B1: Janvier | C1: Février | D1: Mars | E1: Avril | F1: Mai | G1: Juin | H1: Juillet | I1: Aout | J1: Septembre | K1: Octobre | L1: Novembre | M1: Décembre | N1: Total annuel
A3: Total | B3: 1467.8521 | C3: =(sum(C7:C10)-(SUM(C12,C19,C26,C33,C38,C46:C47,C49:C57) )) -> 1446.4721 | D3: =(sum(D7:D10)-(SUM(D12,D19,D26,D33,D38,D46:D47,D49:D57) )) -> 360.15208 | E3: =(sum(E7:E10)-(SUM(E12,E19,E26,E33,E38,E46:E47,E49:E57) )) -> 565.21208 | F3: =(sum(F7:F10)-(SUM(F12,F19,F26,F33,F38,F46:F47,F49:F57) )) -> 138.81208 | G3: =(sum(G7:G10)-(SUM(G12,G19,G26,G33,G38,G46:G47,G49:G57) )) -> -592.62792 | H3: =(sum(H7:H10)-(SUM(H12,H19,H26,H33,H38,H46:H47,H49:H57) )) -> 100.37208 | I3: =(sum(I7:I10)-(SUM(I12,I19,I26,I33,I38,I46:I47,I49:I57) )) -> 1105.6521 | J3: =(sum(J7:J10)-(SUM(J12,J19,J26,J33,J38,J45) )) -> #REF! | K3: =(sum(K7:K10)-(SUM(K12,K19,K26,K33,K38,K45) )) -> #REF! | L3: =(sum(L7:L10)-(SUM(L12,L19,L26,L33,L38,L45) )) -> #REF! | M3: =(sum(M7:M10)-(SUM(M12,M19,M26,M33,M38,M45) )) -> #REF!
A4: Cumul | B4: 1467.8521 | C4: =B3+C3 -> 2914.3242 | D4: =C4+D3 -> 3274.4763 | E4: =D4+E3 -> 3839.6883 | F4: =E4+F3 -> 3978.5004 | G4: =F4+G3 -> 3385.8725 | H4: =G4+H3 -> 3486.2446 | I4: =H4+I3 -> 4591.8967 | J4: =I4+J3 -> #REF! | K4: =J4+K3 -> #REF! | ... M4: =L4+M3 -> #REF! | N4: =M4 -> #REF!
A6: REVENU
A7: Eric | B7: 4052.5333 | C7: 4052.5333 | D7: 4052.5333 | E7: 4052.5333 | F7: 4052.5333 | G7: 4052.5333 | H7: 4052.5333 | I7: 4052.5333 | J7: =((Mensuel!$C$5/4)*3)*0.75+(Mensuel!$C$5/4) -> 3350.1433 | K7: =Mensuel!$C$5 -> 4123.2533 | L7: =Mensuel!$C$5 -> 4123.2533 | M7: =Mensuel!$C$5 -> 4123.2533 | N7: =SUM(B7:M7) -> 48140.17
A8: Maryse | B8: 1539.72 | C8: 1689.1 | D8: 1500 | E8: 1500 | F8: 1500 | G8: 1500 | H8: 1500 | I8: =894.14*2 -> 1788.28 | J8: =894.14*2 -> 1788.28 | K8: =894.14*2 -> 1788.28 | L8: =894.14*2 -> 1788.28 | M8: =894.14*2 -> 1788.28 | N8: =SUM(B8:M8) -> 19670.22
A9: Gouv Qc | B9: 387.84 | E9: 387.84 | H9: =(Mensuel!$C$8*12)/4 -> 1123.57 | K9: 695 | N9: =SUM(B9:M9) -> 2594.25
A10: Gouv Can | B10: 241.85 | C10: 241.85 | D10: 241.85 | E10: 241.85 | F10: 241.85 | G10: 241.85 | H10: 241.85 | I10: 241.85 | J10: =Mensuel!$C$9 -> 691.48 | K10: 631.82 | L10: 631.82 | M10: 631.82 | N10: =SUM(B10:M10) -> 4521.74
A12: MAISON | B12: 1883.1612 | C12: 1883.1612 | D12: 1567.3812 | E12: 1883.1612 | F12: 2260.9812 | G12: 1883.1612 | H12: 2260.9812 | I12: 1883.1612 | J12: =sum(J13:J17) -> 2130.38 | K12: =sum(K13:K17) -> 2130.38 | L12: =sum(L13:L17) -> 2130.38 | M12: =sum(M13:M17) -> 2130.38 | N12: =SUM(B12:M12) -> 24026.67
A13: Hypothèque | B13: 1490 | C13: 1490 | D13: 1490 | E13: 1490 | F13: 1490 | G13: 1490 | H13: 1490 | I13: 1490 | J13: =Mensuel!$C$16 -> 1680 | K13: =Mensuel!$C$16 -> 1680 | L13: =Mensuel!$C$16 -> 1680 | M13: =Mensuel!$C$16 -> 1680 | N13: =SUM(B13:M13) -> 18640
A14: Vers. Anticipé | B14: 200 | C14: 200 | D14: 200 | E14: 200 | F14: 200 | G14: 200 | H14: 200 | I14: 200 | J14: =Mensuel!$C$18 -> 200 | K14: =Mensuel!$C$18 -> 200 | L14: =Mensuel!$C$18 -> 200 | M14: =Mensuel!$C$18 -> 200 | N14: =SUM(B14:M14) -> 2400
A15: Hydro | B15: 135.85125 | C15: 135.85125 | D15: 135.85125 | E15: 135.85125 | F15: 135.85125 | G15: 135.85125 | H15: 135.85125 | I15: 135.85125 | J15: =Mensuel!$C$17 -> 170 | K15: =Mensuel!$C$17 -> 170 | L15: =Mensuel!$C$17 -> 170 | M15: =Mensuel!$C$17 -> 170 | N15: =SUM(B15:M15) -> 1766.81
A16: Ass. Maison | B16: 57.31 | C16: 57.31 | D16: 57.31 | E16: 57.31 | F16: 57.31 | G16: 57.31 | H16: 57.31 | I16: 57.31 | J16: =Mensuel!$C$21 -> 80.38 | K16: =Mensuel!$C$21 -> 80.38 | L16: =Mensuel!$C$21 -> 80.38 | M16: =Mensuel!$C$21 -> 80.38 | N16: =SUM(B16:M16) -> 780
A17: Taxes | D17: -315.78 | F17: 377.82 | H17: 377.82 | N17: =SUM(B17:M17) -> 439.86
A19: AUTO | B19: 1158.58 | C19: 1033.83 | D19: 1033.83 | E19: 1033.83 | F19: 1636.57 | G19: 1033.83 | H19: 2058.58 | I19: 1403.83 | J19: =SUM(J20:J24) -> #REF! | K19: =SUM(K20:K24) -> #REF! | L19: =SUM(L20:L24) -> #REF! | M19: =SUM(M20:M24) -> #REF! | N19: =SUM(B19:M19) -> #REF!
A20: Jeep | B20: 429.34 | C20: 429.34 | D20: 429.34 | E20: 429.34 | F20: 429.34 | G20: 429.34 | H20: 429.34 | I20: 429.34 | J20: =#REF! -> #REF! | K20: =#REF! -> #REF! | L20: =#REF! -> #REF! | M20: =#REF! -> #REF! | N20: =SUM(B20:M20) -> #REF!
A21: Plaques/Permis | B21: 24.75 | C21: 202,74 | F21: 202.74 | H21: 24.75 | N21: =SUM(B21:M21) -> 252.24
A22: Ass. Auto | B22: 104.49 | C22: 104.49 | D22: 104.49 | E22: 104.49 | F22: 104.49 | G22: 104.49 | H22: 104.49 | I22: 104.49 | J22: =Mensuel!$C$22 -> 98.54 | K22: =Mensuel!$C$22 -> 98.54 | L22: =Mensuel!$C$22 -> 98.54 | M22: =Mensuel!$C$22 -> 98.54 | N22: =SUM(B22:M22) -> 1230.08
A23: Gas | B23: 600 | C23: 500 | D23: 500 | E23: 500 | F23: 500 | G23: 500 | H23: 500 | I23: 500 | J23: 300 | K23: 300 | L23: =Mensuel!$C$27 -> 540 | M23: =Mensuel!$C$27 -> 540 | N23: =SUM(B23:M23) -> 5780
A24: Réparation | F24: 400 | H24: 1000 | I24: 220
A26: FINANCE | B26: 411.03 | C26: 545.03 | D26: 545.03 | E26: 545.03 | F26: 545.03 | G26: 545.03 | H26: 545.03 | I26: 545.03 | J26: =SUM(J27:J31) -> 546.18 | K26: =SUM(K27:K31) -> 546.18 | L26: =SUM(L27:L31) -> 546.18 | M26: =SUM(M27:M31) -> 546.18 | N26: =SUM(B26:M26) -> 6410.96
A27: Frais comptes | B27: 40 | C27: 40 | D27: 40 | E27: 40 | F27: 40 | G27: 40 | H27: 40 | I27: 40 | J27: 40 | K27: 40 | L27: 40 | M27: 40 | N27: =SUM(B27:M27) -> 480
